Workbook

Sheet ID_Cidades
A1: nome | B1: id_cidade | C1: LATITUDE | D1: LONGITUDE
A2: 18 de Julio | B2: 314362 | C2: -33.684688 | D2: -53.558255
A3: Abadia de Goiás | B3: 302606 | C3: -16.76206 | D3: -49.438354
A4: Abadia dos Dourados | B4: 304944 | C4: -18.483287 | D4: -47.392467
A5: Abadiânia | B5: 302814 | C5: -16.197423 | D5: -48.706066
A6: Abaeté | B6: 303004 | C6: -19.152155 | D6: -45.455739
A7: Abaetetuba | B7: 301936 | C7: -1.7222087 | D7: -48.879223
A8: Abaí | B8: 314329 | C8: -25.997706 | D8: -55.936002
A9: Abaiara | B9: 300837 | C9: -7.3609456 | D9: -39.048497
A10: Abaíra | B10: 300957 | C10: -13.250724 | D10: -41.664715
A11: Abaré | B11: 301294 | C11: -8.7237544 | D11: -39.11455
A12: Abatiá | B12: 303961 | C12: -23.303989 | D12: -50.312947
A13: Abdon Batista | B13: 305136 | C13: -27.613105 | D13: -51.023718
... A5870: Tallin | B5870: 314543 | C5870: 59.436961 | D5870: 24.753575

Sheet GCD base
A1: Cod Trechos (únicos) | B1: Trechos Únicos | C1: Emb | D1: CodEmbarque | E1: Des | F1: CodDesembarque | G1: Distância (GCD) | H1: Aeroporto (Embarque) | I1: Latitude | J1: Longitude | K1: Aeroporto (Desembarque) | L1: Latitude | M1: Longitude
A2: =D2*F2 -> 87476343695 | B2: =_xlfn.CONCAT(C2,"/",E2) -> João Pessoa/Brasília | C2: João Pessoa | D2: =VLOOKUP(C2,ID_Cidades!$A$1:$D$5870,2,FALSE) -> 295765 | E2: Brasília | F2: =VLOOKUP(E2,ID_Cidades!$A$1:$D$5870,2,FALSE) -> 295763 | G2: 1713.42 | H2: Aeroporto de João Pessoa | I2: -7.1460091 | J2: -34.948776 | K2: Aeroporto de Brasília | L2: -15.869974 | M2: -47.920967
A3: =D3*F3 -> 87480780170 | B3: =_xlfn.CONCAT(C3,"/",E3) -> João Pessoa/Rio de Janeiro | C3: João Pessoa | D3: =VLOOKUP(C3,ID_Cidades!$A$1:$D$5870,2,FALSE) -> 295765 | E3: Rio de Janeiro | F3: =VLOOKUP(E3,ID_Cidades!$A$1:$D$5870,2,FALSE) -> 295778 | G3: 1961.5008 | H3: Aeroporto de João Pessoa | I3: -7.1460091 | J3: -34.948776 | K3: Aeroporto de Rio de Janeiro | L3: -22.906847 | M3: -43.172897
A4: =D4*F4 -> 90113384435 | B4: =_xlfn.CONCAT(C4,"/",E4) -> Rio Branco/João Pessoa | C4: Rio Branco | D4: =VLOOKUP(C4,ID_Cidades!$A$1:$D$5870,2,FALSE) -> 304679 | E4: João Pessoa | F4: =VLOOKUP(E4,ID_Cidades!$A$1:$D$5870,2,FALSE) -> 295765 | G4: 3635.5531 | H4: Aeroporto de Rio Branco | I4: -9.8664358 | J4: -67.897356 | K4: Aeroporto de João Pessoa | L4: -7.1460091 | M4: -34.948776
A5: =D5*F5 -> 90112775077 | B5: =_xlfn.CONCAT(C5,"/",E5) -> Brasília/Rio Branco | C5: Brasília | D5: =VLOOKUP(C5,ID_Cidades!$A$1:$D$5870,2,FALSE) -> 295763 | E5: Rio Branco | F5: =VLOOKUP(E5,ID_Cidades!$A$1:$D$5870,2,FALSE) -> 304679 | G5: 2265.0606 | H5: Aeroporto de Brasília | I5: -15.869974 | J5: -47.920967 | K5: Aeroporto de Rio Branco | L5: -9.8664358 | M5: -67.897356
A6: =D6*F6 -> 87476639458 | B6: =_xlfn.CONCAT(C6,"/",E6) -> Recife/Brasília | C6: Recife | D6: =VLOOKUP(C6,ID_Cidades!$A$1:$D$5870,2,FALSE) -> 295766 | E6: Brasília | F6: =VLOOKUP(E6,ID_Cidades!$A$1:$D$5870,2,FALSE) -> 295763 | G6: 1654.2115 | H6: Aeroporto de Recife | I6: -8.1287392 | J6: -34.925853 | K6: Aeroporto de Brasília | L6: -15.869974 | M6: -47.920967
A7: =D7*F7 -> 90420980035 | B7: =_xlfn.CONCAT(C7,"/",E7) -> Foz do Iguaçu/João Pessoa | C7: Foz do Iguaçu | D7: =VLOOKUP(C7,ID_Cidades!$A$1:$D$5870,2,FALSE) -> 305719 | E7: João Pessoa | F7: =VLOOKUP(E7,ID_Cidades!$A$1:$D$5870,2,FALSE) -> 295765 | G7: 2917.0456 | H7: Aeroporto de Foz do Iguaçu | I7: -25.59778 | J7: -54.488511 | K7: Aeroporto de João Pessoa | L7: -7.1460091 | M7: -34.948776
A8: =D8*F8 -> 90421897192 | B8: =_xlfn.CONCAT(C8,"/",E8) -> Foz do Iguaçu/Maceió | C8: Foz do Iguaçu | D8: =VLOOKUP(C8,ID_Cidades!$A$1:$D$5870,2,FALSE) -> 305719 | E8: Maceió | F8: =VLOOKUP(E8,ID_Cidades!$A$1:$D$5870,2,FALSE) -> 295768 | G8: 2663.6075 | H8: Aeroporto de Foz do Iguaçu | I8: -25.59778 | J8: -54.488511 | K8: Aeroporto de Maceió | L8: -9.5118603 | M8: -35.793183
A9: =D9*F9 -> 87481075935 | B9: =_xlfn.CONCAT(C9,"/",E9) -> São Paulo/João Pessoa | C9: São Paulo | D9: =VLOOKUP(C9,ID_Cidades!$A$1:$D$5870,2,FALSE) -> 295779 | E9: João Pessoa | F9: =VLOOKUP(E9,ID_Cidades!$A$1:$D$5870,2,FALSE) -> 295765 | G9: 2189.9742 | H9: Aeroporto de São Paulo | I9: -23.430218 | J9: -46.471671 | K9: Aeroporto de João Pessoa | L9: -7.1460091 | M9: -34.948776
A10: =D10*F10 -> 87480188640 | B10: =_xlfn.CONCAT(C10,"/",E10) -> Vitória/João Pessoa | C10: Vitória | D10: =VLOOKUP(C10,ID_Cidades!$A$1:$D$5870,2,FALSE) -> 295776 | E10: João Pessoa | F10: =VLOOKUP(E10,ID_Cidades!$A$1:$D$5870,2,FALSE) -> 295765 | G10: 1568.3894 | H10: Aeroporto de Vitória | I10: -20.265512 | J10: -40.282682 | K10: Aeroporto de João Pessoa | L10: -7.1460091 | M10: -34.948776
A11: =D11*F11 -> 87481371700 | B11: =_xlfn.CONCAT(C11,"/",E11) -> João Pessoa/Curitiba | C11: João Pessoa | D11: =VLOOKUP(C11,ID_Cidades!$A$1:$D$5870,2,FALSE) -> 295765 | E11: Curitiba | F11: =VLOOKUP(E11,ID_Cidades!$A$1:$D$5870,2,FALSE) -> 295780 | G11: 2541.6476 | H11: Aeroporto de João Pessoa | I11: -7.1460091 | J11: -34.948776 | K11: Aeroporto de Curitiba | L11: -25.529927 | M11: -49.172387
A12: =D12*F12 -> 87480484405 | B12: =_xlfn.CONCAT(C12,"/",E12) -> João Pessoa/Belo Horizonte | C12: João Pessoa | D12: =VLOOKUP(C12,ID_Cidades!$A$1:$D$5870,2,FALSE) -> 295765 | E12: Belo Horizonte | F12: =VLOOKUP(E12,ID_Cidades!$A$1:$D$5870,2,FALSE) -> 295777 | G12: 1714.8365 | H12: Aeroporto de João Pessoa | I12: -7.1460091 | J12: -34.948776 | K12: Aeroporto de Belo Horizonte | L12: -19.849847 | M12: -43.95489
A13: =D13*F13 -> 89809937432 | B13: =_xlfn.CONCAT(C13,"/",E13) -> Recife/Campinas | C13: Recife | D13: =VLOOKUP(C13,ID_Cidades!$A$1:$D$5870,2,FALSE) -> 295766 | E13: Campinas | F13: =VLOOKUP(E13,ID_Cidades!$A$1:$D$5870,2,FALSE) -> 303652 | G13: 2106.9244 | H13: Aeroporto de Recife | I13: -8.1287392 | J13: -34.925853 | K13: Aeroporto de Campinas | L13: -23.00805 | M13: -47.13966
... A64: =D64*F64 -> 87480484377 | B64: =_xlfn.CONCAT(C64,"/",E64) -> Brasília/São Paulo | C64: Brasília | D64: =VLOOKUP(C64,ID_Cidades!$A$1:$D$5870,2,FALSE) -> 295763 | E64: São Paulo | F64: =VLOOKUP(E64,ID_Cidades!$A$1:$D$5870,2,FALSE) -> 295779 | G64: 854.35577 | H64: Aeroporto de Brasília | I64: -15.870691 | J64: -47.919348 | K64: Aeroporto de São Paulo | L64: -23.430218 | M64: -46.471671
A65: =D65*F65 -> 87478414054 | B65: =_xlfn.CONCAT(C65,"/",E65) -> Recife/Aracaju | C65: Recife | D65: =VLOOKUP(C65,ID_Cidades!$A$1:$D$5870,2,FALSE) -> 295766 | E65: Aracaju | F65: =VLOOKUP(E65,ID_Cidades!$A$1:$D$5870,2,FALSE) -> 295769 | G65: 395.59858 | H65: =_xlfn.CONCAT("Aeroporto de ",C65) -> Aeroporto de Recife | I65: -8.1287392 | J65: -34.925853 | K65: =_xlfn.CONCAT("Aeroporto de ",E65) -> Aeroporto de Aracaju | L65: -10.986989 | M65: -37.072622
A66: =D66*F66 -> 87482258995 | B66: =_xlfn.CONCAT(C66,"/",E66) -> Manaus/João Pessoa | C66: Manaus | D66: =VLOOKUP(C66,ID_Cidades!$A$1:$D$5870,2,FALSE) -> 295783 | E66: João Pessoa | F66: =VLOOKUP(E66,ID_Cidades!$A$1:$D$5870,2,FALSE) -> 295765 | G66: 2817.0983 | H66: =_xlfn.CONCAT("Aeroporto de ",C66) -> Aeroporto de Manaus | I66: -3.0318168 | J66: -60.046077 | K66: =_xlfn.CONCAT("Aeroporto de ",E66) -> Aeroporto de João Pessoa | L66: -7.1460091 | M66: -34.948776
A67: =D67*F67 -> 93026392682 | B67: =_xlfn.CONCAT(C67,"/",E67) -> Washington/Recife | C67: Washington | D67: =VLOOKUP(C67,ID_Cidades!$A$1:$D$5870,2,FALSE) -> 314527 | E67: Recife | F67: =VLOOKUP(E67,ID_Cidades!$A$1:$D$5870,2,FALSE) -> 295766 | G67: 6831.3632 | H67: =_xlfn.CONCAT("Aeroporto de ",C67) -> Aeroporto de Washington | I67: 38.95234 | J67: -77.458634 | K67: =_xlfn.CONCAT("Aeroporto de ",E67) -> Aeroporto de Recife | L67: -8.1287392 | M67: -34.925853
A68: =D68*F68 -> 88922343666 | B68: =_xlfn.CONCAT(C68,"/",E68) -> Boa Vista/Recife | C68: Boa Vista | D68: =VLOOKUP(C68,ID_Cidades!$A$1:$D$5870,2,FALSE) -> 300651 | E68: Recife | F68: =VLOOKUP(E68,ID_Cidades!$A$1:$D$5870,2,FALSE) -> 295766 | G68: 3107.9048 | H68: =_xlfn.CONCAT("Aeroporto de ",C68) -> Aeroporto de Boa Vista | I68: 2.8412191 | J68: -60.692257 | K68: =_xlfn.CONCAT("Aeroporto de ",E68) -> Aeroporto de Recife | L68: -8.1287392 | M68: -34.925853
A69: =D69*F69 -> 87481075948 | B69: =_xlfn.CONCAT(C69,"/",E69) -> Recife/Rio de Janeiro | C69: Recife | D69: =VLOOKUP(C69,ID_Cidades!$A$1:$D$5870,2,FALSE) -> 295766 | E69: Rio de Janeiro | F69: =VLOOKUP(E69,ID_Cidades!$A$1:$D$5870,2,FALSE) -> 295778 | G69: 1864.8173 | H69: =_xlfn.CONCAT("Aeroporto de ",C69) -> Aeroporto de Recife | I69: -8.1287392 | J69: -34.925853 | K69: =_xlfn.CONCAT("Aeroporto de ",E69) -> Aeroporto de Rio de Janeiro | L69: -22.906847 | M69: -43.172897
A70: =D70*F70 -> 89245905690 | B70: =_xlfn.CONCAT(C70,"/",E70) -> João Pessoa/Ilhéus | C70: João Pessoa | D70: =VLOOKUP(C70,ID_Cidades!$A$1:$D$5870,2,FALSE) -> 295765 | E70: Ilhéus | F70: =VLOOKUP(E70,ID_Cidades!$A$1:$D$5870,2,FALSE) -> 301746 | G70: 962.38417 | H70: =_xlfn.CONCAT("Aeroporto de ",C70) -> Aeroporto de João Pessoa | I70: -7.1460091 | J70: -34.948776 | K70: =_xlfn.CONCAT("Aeroporto de ",E70) -> Aeroporto de Ilhéus | L70: -14.815408 | M70: -39.032648
A71: =D71*F71 -> 90370709768 | B71: =_xlfn.CONCAT(C71,"/",E71) -> Recife/Pelotas | C71: Recife | D71: =VLOOKUP(C71,ID_Cidades!$A$1:$D$5870,2,FALSE) -> 295766 | E71: Pelotas | F71: =VLOOKUP(E71,ID_Cidades!$A$1:$D$5870,2,FALSE) -> 305548 | G71: 3182.2206 | H71: =_xlfn.CONCAT("Aeroporto de ",C71) -> Aeroporto de Recife | I71: -8.1287392 | J71: -34.925853 | K71: =_xlfn.CONCAT("Aeroporto de ",E71) -> Aeroporto de Pelotas | L71: -31.715823 | M71: -52.330689
A72: =D72*F72 -> 90370404220 | B72: =_xlfn.CONCAT(C72,"/",E72) -> Pelotas/João Pessoa | C72: Pelotas | D72: =VLOOKUP(C72,ID_Cidades!$A$1:$D$5870,2,FALSE) -> 305548 | E72: João Pessoa | F72: =VLOOKUP(E72,ID_Cidades!$A$1:$D$5870,2,FALSE) -> 295765 | G72: 3273.9793 | H72: =_xlfn.CONCAT("Aeroporto de ",C72) -> Aeroporto de Pelotas | I72: -31.715823 | J72: -52.330689 | K72: =_xlfn.CONCAT("Aeroporto de ",E72) -> Aeroporto de João Pessoa | L72: -7.1460091 | M72: -34.948776
A73: =D73*F73 -> 87486991508 | B73: =_xlfn.CONCAT(C73,"/",E73) -> Rio de Janeiro/Porto Alegre | C73: Rio de Janeiro | D73: =VLOOKUP(C73,ID_Cidades!$A$1:$D$5870,2,FALSE) -> 295778 | E73: Porto Alegre | F73: =VLOOKUP(E73,ID_Cidades!$A$1:$D$5870,2,FALSE) -> 295786 | G73: 1120.3315 | H73: =_xlfn.CONCAT("Aeroporto de ",C73) -> Aeroporto de Rio de Janeiro | I73: -22.906847 | J73: -43.172897 | K73: =_xlfn.CONCAT("Aeroporto de ",E73) -> Aeroporto de Porto Alegre | L73: -29.994942 | M73: -51.176329
A74: =D74*F74 -> 87481963230 | B74: =_xlfn.CONCAT(C74,"/",E74) -> João Pessoa/Cuiabá | C74: João Pessoa | D74: =VLOOKUP(C74,ID_Cidades!$A$1:$D$5870,2,FALSE) -> 295765 | E74: Cuiabá | F74: =VLOOKUP(E74,ID_Cidades!$A$1:$D$5870,2,FALSE) -> 295782 | G74: 2492.0076 | H74: =_xlfn.CONCAT("Aeroporto de ",C74) -> Aeroporto de João Pessoa | I74: -7.1460091 | J74: -34.948776 | K74: =_xlfn.CONCAT("Aeroporto de ",E74) -> Aeroporto de Cuiabá | L74: -15.650604 | M74: -56.120459
A75: =D75*F75 -> 87481963246 | B75: =_xlfn.CONCAT(C75,"/",E75) -> Recife/Florianópolis | C75: Recife | D75: =VLOOKUP(C75,ID_Cidades!$A$1:$D$5870,2,FALSE) -> 295766 | E75: Florianópolis | F75: =VLOOKUP(E75,ID_Cidades!$A$1:$D$5870,2,FALSE) -> 295781 | G75: 2603.2603 | H75: =_xlfn.CONCAT("Aeroporto de ",C75) -> Aeroporto de Recife | I75: -8.1287392 | J75: -34.925853 | K75: =_xlfn.CONCAT("Aeroporto de ",E75) -> Aeroporto de Florianópolis | L75: -27.674547 | M75: -48.546156
A76: =D76*F76 -> 88921233592 | B76: =_xlfn.CONCAT(C76,"/",E76) -> Campina Grande/Florianópolis | C76: Campina Grande | D76: =VLOOKUP(C76,ID_Cidades!$A$1:$D$5870,2,FALSE) -> 300632 | E76: Florianópolis | F76: =VLOOKUP(E76,ID_Cidades!$A$1:$D$5870,2,FALSE) -> 295781 | G76: 2632.0407 | H76: =_xlfn.CONCAT("Aeroporto de ",C76) -> Aeroporto de Campina Grande | I76: -7.2688784 | J76: -35.894021 | K76: =_xlfn.CONCAT("Aeroporto de ",E76) -> Aeroporto de Florianópolis | L76: -27.674547 | M76: -48.546156
... A135: =D135*F135 -> 88915822216 | B135: =_xlfn.CONCAT(C135,"/",E135) -> Campina Grande/Brasília | C135: Campina Grande | D135: =VLOOKUP(C135,ID_Cidades!$A$1:$D$5870,2,FALSE) -> 300632 | E135: Brasília | F135: =VLOOKUP(E135,ID_Cidades!$A$1:$D$5870,2,FALSE) -> 295763 | G135: 1621.2667 | H135: =_xlfn.CONCAT("Aeroporto de ",C135) -> Aeroporto de Campina Grande | I135: -7.2688784 | J135: -35.894021 | K135: =_xlfn.CONCAT("Aeroporto de ",E135) -> Aeroporto de Brasília | L135: -15.870691 | M135: -47.919348
A136: =D136*F136 -> 90259797518 | B136: =_xlfn.CONCAT(C136,"/",E136) -> Recife/Passo Fundo | C136: Recife | D136: =VLOOKUP(C136,ID_Cidades!$A$1:$D$5870,2,FALSE) -> 295766 | E136: Passo Fundo | F136: =VLOOKUP(E136,ID_Cidades!$A$1:$D$5870,2,FALSE) -> 305173 | G136: 2887.3618 | H136: Aeroporto de Recife | I136: -8.1287392 | J136: -34.925853 | K136: Aeroporto de Passo Fundo | L136: -28.240469 | M136: -52.32832
A137: =D137*F137 -> 90264375113 | B137: =_xlfn.CONCAT(C137,"/",E137) -> Passo Fundo/Florianópolis | C137: Passo Fundo | D137: =VLOOKUP(C137,ID_Cidades!$A$1:$D$5870,2,FALSE) -> 305173 | E137: Florianópolis | F137: =VLOOKUP(E137,ID_Cidades!$A$1:$D$5870,2,FALSE) -> 295781 | G137: 376.85749 | H137: Aeroporto de Passo Fundo | I137: -28.240469 | J137: -52.32832 | K137: Aeroporto de Florianópolis | L137: -27.674547 | M137: -48.546156
A138: =D138*F138 -> 93026096916 | B138: =_xlfn.CONCAT(C138,"/",E138) -> Recife/Madri | C138: Recife | D138: =VLOOKUP(C138,ID_Cidades!$A$1:$D$5870,2,FALSE) -> 295766 | E138: Madri | F138: =VLOOKUP(E138,ID_Cidades!$A$1:$D$5870,2,FALSE) -> 314526 | G138: 6290.8569 | H138: Aeroporto de Recife | I138: -8.1287392 | J138: -34.925853 | K138: Aeroporto de Madri | L138: 40.489515 | M138: -3.5642764
A139: =D139*F139 -> 89367169340 | B139: =_xlfn.CONCAT(C139,"/",E139) -> Montes Claros/João Pessoa | C139: Montes Claros | D139: =VLOOKUP(C139,ID_Cidades!$A$1:$D$5870,2,FALSE) -> 302156 | E139: João Pessoa | F139: =VLOOKUP(E139,ID_Cidades!$A$1:$D$5870,2,FALSE) -> 295765 | G139: 1435.2349 | H139: Aeroporto de Montes Claros | I139: -16.704953 | J139: -43.819986 | K139: Aeroporto de João Pessoa | L139: -7.1460091 | M139: -34.948776
A140: =D140*F140 -> 93030481533 | B140: =_xlfn.CONCAT(C140,"/",E140) -> São Paulo/Washington | C140: São Paulo | D140: =VLOOKUP(C140,ID_Cidades!$A$1:$D$5870,2,FALSE) -> 295779 | E140: Washington | F140: =VLOOKUP(E140,ID_Cidades!$A$1:$D$5870,2,FALSE) -> 314527 | G140: 7651.6346 | H140: Aeroporto de São Paulo | I140: -23.430218 | J140: -46.471671 | K140: Aeroporto de Washington | L140: 38.95234 | M140: -77.458634
A141: =D141*F141 -> 89935038140 | B141: =_xlfn.CONCAT(C141,"/",E141) -> João Pessoa/Jaguaruna | C141: João Pessoa | D141: =VLOOKUP(C141,ID_Cidades!$A$1:$D$5870,2,FALSE) -> 295765 | E141: Jaguaruna | F141: =VLOOKUP(E141,ID_Cidades!$A$1:$D$5870,2,FALSE) -> 304076 | G141: 2808.934 | H141: Aeroporto de João Pessoa | I141: -7.1460091 | J141: -34.948776 | K141: Aeroporto de Jaguaruna | L141: -28.621121 | M141: -49.024983
A142: =D142*F142 -> 89650223792 | B142: =_xlfn.CONCAT(C142,"/",E142) -> Recife/Juiz de Fora | C142: Recife | D142: =VLOOKUP(C142,ID_Cidades!$A$1:$D$5870,2,FALSE) -> 295766 | E142: Juiz de Fora | F142: =VLOOKUP(E142,ID_Cidades!$A$1:$D$5870,2,FALSE) -> 303112 | G142: 1769.4701 | H142: Aeroporto de Recife | I142: -8.1287392 | J142: -34.925853 | K142: Aeroporto de Juiz de Fora | L142: -21.791975 | M142: -43.385565
A143: =D143*F143 -> 90424954382 | B143: =_xlfn.CONCAT(C143,"/",E143) -> Rio de Janeiro/Foz do Iguaçu | C143: Rio de Janeiro | D143: =VLOOKUP(C143,ID_Cidades!$A$1:$D$5870,2,FALSE) -> 295778 | E143: Foz do Iguaçu | F143: =VLOOKUP(E143,ID_Cidades!$A$1:$D$5870,2,FALSE) -> 305719 | G143: 1185.4378 | H143: Aeroporto de Rio de Janeiro | I143: -22.906847 | J143: -43.172897 | K143: Aeroporto de Foz do Iguaçu | L143: -25.59778 | M143: -54.488511
A144: =D144*F144 -> 89893910457 | B144: =_xlfn.CONCAT(C144,"/",E144) -> Guarulhos/Brasília | C144: Guarulhos | D144: =VLOOKUP(C144,ID_Cidades!$A$1:$D$5870,2,FALSE) -> 303939 | E144: Brasília | F144: =VLOOKUP(E144,ID_Cidades!$A$1:$D$5870,2,FALSE) -> 295763 | G144: 854.35577 | H144: Aeroporto de Guarulhos | I144: -23.430218 | J144: -46.471671 | K144: Aeroporto de Brasília | L144: -15.870691 | M144: -47.919348
A145: =D145*F145 -> 89809330128 | B145: =_xlfn.CONCAT(C145,"/",E145) -> Natal/Campinas | C145: Natal | D145: =VLOOKUP(C145,ID_Cidades!$A$1:$D$5870,2,FALSE) -> 295764 | E145: Campinas | F145: =VLOOKUP(E145,ID_Cidades!$A$1:$D$5870,2,FALSE) -> 303652 | G145: 2295.9291 | H145: Aeroporto de Natal | I145: -5.7632583 | J145: -35.372699 | K145: Aeroporto de Campinas | L145: -23.00805 | M145: -47.13966
A146: =D146*F146 -> 89564444595 | B146: =_xlfn.CONCAT(C146,"/",E146) -> Confins/João Pessoa | C146: Confins | D146: =VLOOKUP(C146,ID_Cidades!$A$1:$D$5870,2,FALSE) -> 302823 | E146: João Pessoa | F146: =VLOOKUP(E146,ID_Cidades!$A$1:$D$5870,2,FALSE) -> 295765 | G146: 1696.1051 | H146: Aeroporto de Confins | I146: -19.634872 | J146: -43.964871 | K146: Aeroporto de João Pessoa | L146: -7.1460091 | M146: -34.948776
A147: =D147*F147 -> 88879161830 | B147: =_xlfn.CONCAT(C147,"/",E147) -> Recife/Santa Maria | C147: Recife | D147: =VLOOKUP(C147,ID_Cidades!$A$1:$D$5870,2,FALSE) -> 295766 | E147: Santa Maria | F147: =VLOOKUP(E147,ID_Cidades!$A$1:$D$5870,2,FALSE) -> 300505 | G147: 3097.8757 | H147: Aeroporto de Recife | I147: -8.1287392 | J147: -34.925853 | K147: Aeroporto de Santa Maria | L147: -29.708357 | M147: -53.700504
... A165: =D165*F165 -> 90377798345 | B165: =_xlfn.CONCAT(C165,"/",E165) -> Presidente Prudente/João Pessoa | C165: Presidente Prudente | D165: =VLOOKUP(C165,ID_Cidades!$A$1:$D$5870,2,FALSE) -> 305573 | E165: João Pessoa | F165: =VLOOKUP(E165,ID_Cidades!$A$1:$D$5870,2,FALSE) -> 295765 | G165: 2431.6488 | H165: Aeroporto de Presidente Prudente | I165: -22.179103 | J165: -51.417322 | K165: Aeroporto de João Pessoa | L165: -7.1460091 | M165: -34.948776
...
