Workbook
Name SegmentaçãodeDados_Dias_de_viagem2: #N/A
Name SegmentaçãodeDados_dsh__dmh_ou_dlh: #N/A
Name SegmentaçãodeDados_Viagem_Urgente_sem_justificativa: #N/A
Name SegmentaçãodeDados_Vínculo_Institucional: #N/A

Sheet Entradas
A1: aux | B1: Identificador do processo de viagem | C1: Número da Proposta (PCDP) | D1: CPF viajante | E1: Nome | F1: Cargo | G1: Função | H1: Descrição Função | I1: Período - Data de início | J1: Período - Data de fim | K1: Motivo | L1: Origem - Data | M1: Destino - Data | N1: Origem - Cidade | O1: Destino - Cidade | P1: Cod Embarque | Q1: Cod Desembarque | R1: Cod Trecho | S1: Distância (km) | T1: Meio de transporte | U1: Missao? | V1: Situação | W1: Viagem Urgente | X1: Justificativa Urgência Viagem | Y1: Valor diárias | Z1: Valor outros gastos | AA1: Valor da passagem | AB1: Taxa de serviço | AC1: Data da emissão/compra | AD1: Classe | AE1: dsh, dmh ou dlh | AF1: EF | AG1: Emissões
A2: =COUNTIF($B$2:B2,B2) -> 1 | B2: 19001658 | C2: 000450/23 | D2: ***.518.375-** | E2: ANGELA DE OLIVEIRA CARNEIRO | F2: PROFESSOR DO MAGISTERIO SUPERIOR | G2: -1 | H2: Sem informação | I2: 45109 | J2: 45121 | K2: O PROPOSTO IRÁ PARTICIPAR COMO MEMBRO DE BANCA DE CONCURSO PÚBLICO DO DEPARTAMENTO DE ENFERMAGEM CLÍNICA | L2: 45109 | M2: 45121 | N2: Petrolina | O2: João Pessoa | P2: =VLOOKUP(N2,[1]ID_Cidades!$A$1:$E$5900,2,FALSE) -> 301428 | Q2: =VLOOKUP(O2,[1]ID_Cidades!$A$1:$E$5900,2,FALSE) -> 295765 | R2: =P2*Q2 -> 89151852420 | S2: =VLOOKUP(R2,'[1]GCD base'!$A$1:$M$200,7,FALSE) -> 665.73966 | T2: Aéreo | U2: Sim | V2: Realizada | W2: SIM | X2: justificativa em anexo. | Y2: 4058.65 | Z2: 0 | AA2: 2260.99 | AB2: 0 | AC2: 45097 | AD2: Econômica | AE2: {=_xlfn.IFS(S2<=Constantes!$G$2,"Muito Curta (evitável)",S2<=Constantes!$H$2,"Curta Distância",S2>Constantes!$H$2,"Longa Distância")} -> Curta Distância | AF2: =IFERROR(VLOOKUP(AE2,Constantes!$A$1:$E$5,MATCH(AD2,Constantes!$A$1:$E$1,0),0),"") -> 0.18286935 | AG2: =AF2*S2 -> 121.74338
A3: =COUNTIF($B$2:B3,B3) -> 2 | B3: 19001658 | C3: 000450/23 | D3: ***.518.375-** | E3: ANGELA DE OLIVEIRA CARNEIRO | F3: PROFESSOR DO MAGISTERIO SUPERIOR | G3: -1 | H3: Sem informação | I3: 45109 | J3: 45121 | K3: O PROPOSTO IRÁ PARTICIPAR COMO MEMBRO DE BANCA DE CONCURSO PÚBLICO DO DEPARTAMENTO DE ENFERMAGEM CLÍNICA | L3: 45121 | M3: 45121 | N3: João Pessoa | O3: Petrolina | P3: =VLOOKUP(N3,[1]ID_Cidades!$A$1:$E$5900,2,FALSE) -> 295765 | Q3: =VLOOKUP(O3,[1]ID_Cidades!$A$1:$E$5900,2,FALSE) -> 301428 | R3: =P3*Q3 -> 89151852420 | S3: =VLOOKUP(R3,'[1]GCD base'!$A$1:$M$200,7,FALSE) -> 665.73966 | T3: Aéreo | U3: Não | V3: Realizada | W3: SIM | X3: justificativa em anexo. | Y3: 0 | Z3: 0 | AA3: 2619.99 | AB3: 0 | AC3: 45097 | AD3: Econômica | AE3: {=_xlfn.IFS(S3<=Constantes!$G$2,"Muito Curta (evitável)",S3<=Constantes!$H$2,"Curta Distância",S3>Constantes!$H$2,"Longa Distância")} -> Curta Distância | AF3: =IFERROR(VLOOKUP(AE3,Constantes!$A$1:$E$5,MATCH(AD3,Constantes!$A$1:$E$1,0),0),"") -> 0.18286935 | AG3: =AF3*S3 -> 121.74338
A4: =COUNTIF($B$2:B4,B4) -> 1 | B4: 19016293 | C4: 000452/23 | D4: ***.187.354-** | E4: MARIA FATIMA DE SOUSA | F4: PROFESSOR DO MAGISTERIO SUPERIOR | G4: -1 | H4: Sem informação | I4: 45109 | J4: 45122 | K4: O PROPOSTO IRÁ PARTICIPAR COMO MEMBRO DE BANCA DE CONCURSO PÚBLICO DO DEPARTAMENTO DE ENFERMAGEM CLÍNICA | L4: 45122 | M4: 45122 | N4: João Pessoa | O4: Brasília | P4: =VLOOKUP(N4,[1]ID_Cidades!$A$1:$E$5900,2,FALSE) -> 295765 | Q4: =VLOOKUP(O4,[1]ID_Cidades!$A$1:$E$5900,2,FALSE) -> 295763 | R4: =P4*Q4 -> 87476343695 | S4: =VLOOKUP(R4,'[1]GCD base'!$A$1:$M$200,7,FALSE) -> 1713.42 | T4: Aéreo | U4: Não | V4: Realizada | W4: SIM | X4: justificativa em anexo. | Y4: 4399.67 | Z4: 0 | AA4: 1639.97 | AB4: 0 | AC4: 45097 | AD4: Econômica | AE4: {=_xlfn.IFS(S4<=Constantes!$G$2,"Muito Curta (evitável)",S4<=Constantes!$H$2,"Curta Distância",S4>Constantes!$H$2,"Longa Distância")} -> Curta Distância | AF4: =IFERROR(VLOOKUP(AE4,Constantes!$A$1:$E$5,MATCH(AD4,Constantes!$A$1:$E$1,0),0),"") -> 0.18286935 | AG4: =AF4*S4 -> 313.33201
A5: =COUNTIF($B$2:B5,B5) -> 2 | B5: 19016293 | C5: 000452/23 | D5: ***.187.354-** | E5: MARIA FATIMA DE SOUSA | F5: PROFESSOR DO MAGISTERIO SUPERIOR | G5: -1 | H5: Sem informação | I5: 45109 | J5: 45122 | K5: O PROPOSTO IRÁ PARTICIPAR COMO MEMBRO DE BANCA DE CONCURSO PÚBLICO DO DEPARTAMENTO DE ENFERMAGEM CLÍNICA | L5: 45109 | M5: 45122 | N5: Brasília | O5: João Pessoa | P5: =VLOOKUP(N5,[1]ID_Cidades!$A$1:$E$5900,2,FALSE) -> 295763 | Q5: =VLOOKUP(O5,[1]ID_Cidades!$A$1:$E$5900,2,FALSE) -> 295765 | R5: =P5*Q5 -> 87476343695 | S5: =VLOOKUP(R5,'[1]GCD base'!$A$1:$M$200,7,FALSE) -> 1713.42 | T5: Aéreo | U5: Sim | V5: Realizada | W5: SIM | X5: justificativa em anexo. | Y5: 0 | Z5: 0 | AA5: 950.99 | AB5: 0 | AC5: 45097 | AD5: Econômica | AE5: {=_xlfn.IFS(S5<=Constantes!$G$2,"Muito Curta (evitável)",S5<=Constantes!$H$2,"Curta Distância",S5>Constantes!$H$2,"Longa Distância")} -> Curta Distância | AF5: =IFERROR(VLOOKUP(AE5,Constantes!$A$1:$E$5,MATCH(AD5,Constantes!$A$1:$E$1,0),0),"") -> 0.18286935 | AG5: =AF5*S5 -> 313.33201
A6: =COUNTIF($B$2:B6,B6) -> 1 | B6: 19019910 | C6: 000457/23 | D6: ***.105.073-** | E6: ROBERTA MENESES OLIVEIRA | F6: PROFESSOR DO MAGISTERIO SUPERIOR | G6: -1 | H6: Sem informação | I6: 45109 | J6: 45122 | K6: O PROPOSTO IRÁ PARTICIPAR COMO MEMBRO DE BANCA DE CONCURSO PÚBLICO DO DEPARTAMENTO DE ENFERMAGEM CLÍNICA | L6: 45109 | M6: 45122 | N6: Fortaleza | O6: João Pessoa | P6: =VLOOKUP(N6,[1]ID_Cidades!$A$1:$E$5900,2,FALSE) -> 314439 | Q6: =VLOOKUP(O6,[1]ID_Cidades!$A$1:$E$5900,2,FALSE) -> 295765 | R6: =P6*Q6 -> 93000050835 | S6: =VLOOKUP(R6,'[1]GCD base'!$A$1:$M$200,7,FALSE) -> 546.23643 | T6: Aéreo | U6: Sim | V6: Realizada | W6: SIM | X6: justificativa em anexo. | Y6: 4399.67 | Z6: 0 | AA6: 1112.61 | AB6: 0 | AC6: 45098 | AD6: Econômica | AE6: {=_xlfn.IFS(S6<=Constantes!$G$2,"Muito Curta (evitável)",S6<=Constantes!$H$2,"Curta Distância",S6>Constantes!$H$2,"Longa Distância")} -> Muito Curta (evitável) | AF6: =IFERROR(VLOOKUP(AE6,Constantes!$A$1:$E$5,MATCH(AD6,Constantes!$A$1:$E$1,0),0),"") -> 0.27257679 | AG6: =AF6*S6 -> 148.89137 | AI6: =COUNTIF(AE:AE,"Muito Curta (evitável)") -> 53
A7: =COUNTIF($B$2:B7,B7) -> 2 | B7: 19019910 | C7: 000457/23 | D7: ***.105.073-** | E7: ROBERTA MENESES OLIVEIRA | F7: PROFESSOR DO MAGISTERIO SUPERIOR | G7: -1 | H7: Sem informação | I7: 45109 | J7: 45122 | K7: O PROPOSTO IRÁ PARTICIPAR COMO MEMBRO DE BANCA DE CONCURSO PÚBLICO DO DEPARTAMENTO DE ENFERMAGEM CLÍNICA | L7: 45122 | M7: 45122 | N7: João Pessoa | O7: Fortaleza | P7: =VLOOKUP(N7,[1]ID_Cidades!$A$1:$E$5900,2,FALSE) -> 295765 | Q7: =VLOOKUP(O7,[1]ID_Cidades!$A$1:$E$5900,2,FALSE) -> 314439 | R7: =P7*Q7 -> 93000050835 | S7: =VLOOKUP(R7,'[1]GCD base'!$A$1:$M$200,7,FALSE) -> 546.23643 | T7: Aéreo | U7: Não | V7: Realizada | W7: SIM | X7: justificativa em anexo. | Y7: 0 | Z7: 0 | AA7: 597.09 | AB7: 0 | AC7: 45098 | AD7: Econômica | AE7: {=_xlfn.IFS(S7<=Constantes!$G$2,"Muito Curta (evitável)",S7<=Constantes!$H$2,"Curta Distância",S7>Constantes!$H$2,"Longa Distância")} -> Muito Curta (evitável) | AF7: =IFERROR(VLOOKUP(AE7,Constantes!$A$1:$E$5,MATCH(AD7,Constantes!$A$1:$E$1,0),0),"") -> 0.27257679 | AG7: =AF7*S7 -> 148.89137
A8: =COUNTIF($B$2:B8,B8) -> 1 | B8: 19041737 | C8: 000481/23-3C | D8: ***.567.773-** | E8: BERLA MOREIRA DE MORAES | F8: PROFESSOR DO MAGISTERIO SUPERIOR | G8: CD-0002 | H8: Cargo Comissionado de Direção | I8: 45110 | J8: 45113 | K8: Participar do I ENCONTRO NACIONAL DE CULTURA & ARTE NAS UNIVERSIDADES FEDERAIS BRASILEIRAS, em Salvador/BA, no período de 03 a 05/07/2023 | L8: 45110 | M8: 45113 | N8: João Pessoa | O8: Salvador | P8: =VLOOKUP(N8,[1]ID_Cidades!$A$1:$E$5900,2,FALSE) -> 295765 | Q8: =VLOOKUP(O8,[1]ID_Cidades!$A$1:$E$5900,2,FALSE) -> 295770 | R8: =P8*Q8 -> 87478414050 | S8: =VLOOKUP(R8,'[1]GCD base'!$A$1:$M$200,7,FALSE) -> 741.11941 | T8: Aéreo | U8: Sim | V8: Realizada | W8: SIM | X8: 0 convite para participar do evento chegou fora do prazo, conforme justificativa no formulário de solicitação | Y8: 1720.73 | Z8: 0 | AA8: 2590.09 | AB8: 0 | AC8: 45104 | AD8: Econômica | AE8: {=_xlfn.IFS(S8<=Constantes!$G$2,"Muito Curta (evitável)",S8<=Constantes!$H$2,"Curta Distância",S8>Constantes!$H$2,"Longa Distância")} -> Curta Distância | AF8: =IFERROR(VLOOKUP(AE8,Constantes!$A$1:$E$5,MATCH(AD8,Constantes!$A$1:$E$1,0),0),"") -> 0.18286935 | AG8: =AF8*S8 -> 135.52803
A9: =COUNTIF($B$2:B9,B9) -> 2 | B9: 19041737 | C9: 000481/23-3C | D9: ***.567.773-** | E9: BERLA MOREIRA DE MORAES | F9: PROFESSOR DO MAGISTERIO SUPERIOR | G9: CD-0002 | H9: Cargo Comissionado de Direção | I9: 45110 | J9: 45113 | K9: Participar do I ENCONTRO NACIONAL DE CULTURA & ARTE NAS UNIVERSIDADES FEDERAIS BRASILEIRAS, em Salvador/BA, no período de 03 a 05/07/2023 | L9: 45113 | M9: 45113 | N9: Salvador | O9: João Pessoa | P9: =VLOOKUP(N9,[1]ID_Cidades!$A$1:$E$5900,2,FALSE) -> 295770 | Q9: =VLOOKUP(O9,[1]ID_Cidades!$A$1:$E$5900,2,FALSE) -> 295765 | R9: =P9*Q9 -> 87478414050 | S9: =VLOOKUP(R9,'[1]GCD base'!$A$1:$M$200,7,FALSE) -> 741.11941 | T9: Aéreo | U9: Não | V9: Realizada | W9: SIM | X9: 0 convite para participar do evento chegou fora do prazo, conforme justificativa no formulário de solicitação | Y9: 0 | Z9: 0 | AA9: 1104.36 | AB9: 0 | AC9: 45104 | AD9: Econômica | AE9: {=_xlfn.IFS(S9<=Constantes!$G$2,"Muito Curta (evitável)",S9<=Constantes!$H$2,"Curta Distância",S9>Constantes!$H$2,"Longa Distância")} -> Curta Distância | AF9: =IFERROR(VLOOKUP(AE9,Constantes!$A$1:$E$5,MATCH(AD9,Constantes!$A$1:$E$1,0),0),"") -> 0.18286935 | AG9: =AF9*S9 -> 135.52803
A10: =COUNTIF($B$2:B10,B10) -> 1 | B10: 19041166 | C10: 000484/23 | D10: ***.028.207-** | E10: MARCELO FERNANDES | G10: -1 | H10: Sem informação | I10: 45112 | J10: 45114 | K10: Ministrar um mini-curso e seminário acadêmico no PPGE/CCSA, nos dias 06 e 07 de julho de 2023. | L10: 45114 | M10: 45114 | N10: João Pessoa | O10: São Paulo | P10: =VLOOKUP(N10,[1]ID_Cidades!$A$1:$E$5900,2,FALSE) -> 295765 | Q10: =VLOOKUP(O10,[1]ID_Cidades!$A$1:$E$5900,2,FALSE) -> 295779 | R10: =P10*Q10 -> 87481075935 | S10: =VLOOKUP(R10,'[1]GCD base'!$A$1:$M$200,7,FALSE) -> 2189.9742 | T10: Aéreo | U10: Não | V10: Realizada | W10: SIM | X10: Aguardava-se a liberação dos recurso do PROAP, por essa razão, não foi solicitado antes. | Y10: 947.55 | Z10: 0 | AA10: 1265.73 | AB10: 0 | AC10: 45105 | AD10: Econômica | AE10: {=_xlfn.IFS(S10<=Constantes!$G$2,"Muito Curta (evitável)",S10<=Constantes!$H$2,"Curta Distância",S10>Constantes!$H$2,"Longa Distância")} -> Curta Distância | AF10: =IFERROR(VLOOKUP(AE10,Constantes!$A$1:$E$5,MATCH(AD10,Constantes!$A$1:$E$1,0),0),"") -> 0.18286935 | AG10: =AF10*S10 -> 400.47918
A11: =COUNTIF($B$2:B11,B11) -> 2 | B11: 19041166 | C11: 000484/23 | D11: ***.028.207-** | E11: MARCELO FERNANDES | G11: -1 | H11: Sem informação | I11: 45112 | J11: 45114 | K11: Ministrar um mini-curso e seminário acadêmico no PPGE/CCSA, nos dias 06 e 07 de julho de 2023. | L11: 45112 | M11: 45114 | N11: São Paulo | O11: João Pessoa | P11: =VLOOKUP(N11,[1]ID_Cidades!$A$1:$E$5900,2,FALSE) -> 295779 | Q11: =VLOOKUP(O11,[1]ID_Cidades!$A$1:$E$5900,2,FALSE) -> 295765 | R11: =P11*Q11 -> 87481075935 | S11: =VLOOKUP(R11,'[1]GCD base'!$A$1:$M$200,7,FALSE) -> 2189.9742 | T11: Aéreo | U11: Sim | V11: Realizada | W11: SIM | X11: Aguardava-se a liberação dos recurso do PROAP, por essa razão, não foi solicitado antes. | Y11: 0 | Z11: 0 | AA11: 1882.09 | AB11: 0 | AC11: 45105 | AD11: Econômica | AE11: {=_xlfn.IFS(S11<=Constantes!$G$2,"Muito Curta (evitável)",S11<=Constantes!$H$2,"Curta Distância",S11>Constantes!$H$2,"Longa Distância")} -> Curta Distância | AF11: =IFERROR(VLOOKUP(AE11,Constantes!$A$1:$E$5,MATCH(AD11,Constantes!$A$1:$E$1,0),0),"") -> 0.18286935 | AG11: =AF11*S11 -> 400.47918
A12: =COUNTIF($B$2:B12,B12) -> 1 | B12: 19062585 | C12: 000508/23 | D12: ***.731.370-** | E12: SERGIO BOTTON BARCELLOS | F12: PROFESSOR DO MAGISTERIO SUPERIOR | G12: FUC-0001 | H12: FUC-0001 | I12: 45117 | J12: 45122 | K12: Participação no 21º Congresso Brasileiro de Sociologia para mediação de um Comitê de Pesquisa e apresentação de um trabalho em GT. Ao mesmo tempo irei representando o PPGS-UFOB como coordenador na Plenária de Programas da área de Sociologia. | L12: 45117 | M12: 45122 | N12: João Pessoa | O12: Belém | P12: =VLOOKUP(N12,[1]ID_Cidades!$A$1:$E$5900,2,FALSE) -> 295765 | Q12: =VLOOKUP(O12,[1]ID_Cidades!$A$1:$E$5900,2,FALSE) -> 300439 | R12: =P12*Q12 -> 88859340835 | S12: =VLOOKUP(R12,'[1]GCD base'!$A$1:$M$200,7,FALSE) -> 1631.4561 | T12: Aéreo | U12: Sim | V12: Realizada | W12: SIM | X12: Recurso PROAP não foi disponibilizado com antecedência. | Y12: 1821.06 | Z12: 0 | AA12: 5292.78 | AB12: 0 | AC12: 45113 | AD12: Econômica | AE12: {=_xlfn.IFS(S12<=Constantes!$G$2,"Muito Curta (evitável)",S12<=Constantes!$H$2,"Curta Distância",S12>Constantes!$H$2,"Longa Distância")} -> Curta Distância | AF12: =IFERROR(VLOOKUP(AE12,Constantes!$A$1:$E$5,MATCH(AD12,Constantes!$A$1:$E$1,0),0),"") -> 0.18286935 | AG12: =AF12*S12 -> 298.34333
A13: =COUNTIF($B$2:B13,B13) -> 2 | B13: 19062585 | C13: 000508/23 | D13: ***.731.370-** | E13: SERGIO BOTTON BARCELLOS | F13: PROFESSOR DO MAGISTERIO SUPERIOR | G13: FUC-0001 | H13: FUC-0001 | I13: 45117 | J13: 45122 | K13: Participação no 21º Congresso Brasileiro de Sociologia para mediação de um Comitê de Pesquisa e apresentação de um trabalho em GT. Ao mesmo tempo irei representando o PPGS-UFOB como coordenador na Plenária de Programas da área de Sociologia. | L13: 45122 | M13: 45122 | N13: Belém | O13: João Pessoa | P13: =VLOOKUP(N13,[1]ID_Cidades!$A$1:$E$5900,2,FALSE) -> 300439 | Q13: =VLOOKUP(O13,[1]ID_Cidades!$A$1:$E$5900,2,FALSE) -> 295765 | R13: =P13*Q13 -> 88859340835 | S13: =VLOOKUP(R13,'[1]GCD base'!$A$1:$M$200,7,FALSE) -> 1631.4561 | T13: Aéreo | U13: Não | V13: Realizada | W13: SIM | X13: Recurso PROAP não foi disponibilizado com antecedência. | Y13: 0 | Z13: 0 | AA13: 0 | AB13: 0 | AC13: 0 | AD13: Econômica | AE13: {=_xlfn.IFS(S13<=Constantes!$G$2,"Muito Curta (evitável)",S13<=Constantes!$H$2,"Curta Distância",S13>Constantes!$H$2,"Longa Distância")} -> Curta Distância | AF13: =IFERROR(VLOOKUP(AE13,Constantes!$A$1:$E$5,MATCH(AD13,Constantes!$A$1:$E$1,0),0),"") -> 0.18286935 | AG13: =AF13*S13 -> 298.34333
A14: =COUNTIF($B$2:B14,B14) -> 1 | B14: 19065213 | C14: 000509/23 | D14: ***.585.343-** | E14: TERESA CRISTINA FURTADO MATOS | F14: PROFESSOR DO MAGISTERIO SUPERIOR | G14: -1 | H14: Sem informação | I14: 45117 | J14: 45122 | K14: Participação no 21º Congresso Brasileiro de Sociologia, com apresentação de trabalho no GT 10 do evento. | L14: 45117 | M14: 45122 | N14: João Pessoa | O14: Belém | P14: =VLOOKUP(N14,[1]ID_Cidades!$A$1:$E$5900,2,FALSE) -> 295765 | Q14: =VLOOKUP(O14,[1]ID_Cidades!$A$1:$E$5900,2,FALSE) -> 300439 | R14: =P14*Q14 -> 88859340835 | S14: =VLOOKUP(R14,'[1]GCD base'!$A$1:$M$200,7,FALSE) -> 1631.4561 | T14: Aéreo | U14: Sim | V14: Realizada | W14: SIM | X14: PROAP não foi liberado anteriormente. | Y14: 1821.06 | Z14: 0 | AA14: 5292.78 | AB14: 0 | AC14: 45114 | AD14: Econômica | AE14: {=_xlfn.IFS(S14<=Constantes!$G$2,"Muito Curta (evitável)",S14<=Constantes!$H$2,"Curta Distância",S14>Constantes!$H$2,"Longa Distância")} -> Curta Distância | AF14: =IFERROR(VLOOKUP(AE14,Constantes!$A$1:$E$5,MATCH(AD14,Constantes!$A$1:$E$1,0),0),"") -> 0.18286935 | AG14: =AF14*S14 -> 298.34333
A15: =COUNTIF($B$2:B15,B15) -> 2 | B15: 19065213 | C15: 000509/23 | D15: ***.585.343-** | E15: TERESA CRISTINA FURTADO MATOS | F15: PROFESSOR DO MAGISTERIO SUPERIOR | G15: -1 | H15: Sem informação | I15: 45117 | J15: 45122 | K15: Participação no 21º Congresso Brasileiro de Sociologia, com apresentação de trabalho no GT 10 do evento. | L15: 45122 | M15: 45122 | N15: Belém | O15: João Pessoa | P15: =VLOOKUP(N15,[1]ID_Cidades!$A$1:$E$5900,2,FALSE) -> 300439 | Q15: =VLOOKUP(O15,[1]ID_Cidades!$A$1:$E$5900,2,FALSE) -> 295765 | R15: =P15*Q15 -> 88859340835 | S15: =VLOOKUP(R15,'[1]GCD base'!$A$1:$M$200,7,FALSE) -> 1631.4561 | T15: Aéreo | U15: Não | V15: Realizada | W15: SIM | X15: PROAP não foi liberado anteriormente. | Y15: 0 | Z15: 0 | AA15: 0 | AB15: 0 | AC15: 0 | AD15: Econômica | AE15: {=_xlfn.IFS(S15<=Constantes!$G$2,"Muito Curta (evitável)",S15<=Constantes!$H$2,"Curta Distância",S15>Constantes!$H$2,"Longa Distância")} -> Curta Distância | AF15: =IFERROR(VLOOKUP(AE15,Constantes!$A$1:$E$5,MATCH(AD15,Constantes!$A$1:$E$1,0),0),"") -> 0.18286935 | AG15: =AF15*S15 -> 298.34333
A16: =COUNTIF($B$2:B16,B16) -> 1 | B16: 19012122 | C16: 000532/23 | D16: ***.103.474-** | E16: HIDELBRANDO JOSE FARKAT DIOGENES | F16: PROFESSOR DO MAGISTERIO SUPERIOR | G16: FUC-0001 | H16: FUC-0001 | I16: 45118 | J16: 45123 | K16: Trata-se da participação em evento científico internacional, a fim de divulgar resultados parciais do doutoramento de Lays Costa, aluna do PPGECAM sob orientação do Prof. Hidelbrando José Farkat Diógenes. | L16: 45122 | M16: 45123 | N16: Santiago | O16: João Pessoa | P16: =VLOOKUP(N16,[1]ID_Cidades!$A$1:$E$5900,2,FALSE) -> 305806 | Q16: =VLOOKUP(O16,[1]ID_Cidades!$A$1:$E$5900,2,FALSE) -> 295765 | R16: =P16*Q16 -> 90446711590 | S16: =VLOOKUP(R16,'[1]GCD base'!$A$1:$M$200,7,FALSE) -> 4701.6614 | T16: Aéreo | U16: Não | V16: Realizada | W16: SIM | X16: A viagem só pode ser cadastrada nesta data devido ao recurso do PROAP destinado ao pagamento da despesa só foi liberado dia 05/07 e estávamos aguardando, também, a realização do empenho específico. | Y16: 4252.24 | Z16: 0 | AA16: 6690.84 | AB16: 0 | AC16: 45113 | AD16: Econômica | AE16: {=_xlfn.IFS(S16<=Constantes!$G$2,"Muito Curta (evitável)",S16<=Constantes!$H$2,"Curta Distância",S16>Constantes!$H$2,"Longa Distância")} -> Longa Distância | AF16: =IFERROR(VLOOKUP(AE16,Constantes!$A$1:$E$5,MATCH(AD16,Constantes!$A$1:$E$1,0),0),"") -> 0.20010828 | AG16: =AF16*S16 -> 940.84139
A17: =COUNTIF($B$2:B17,B17) -> 2 | B17: 19012122 | C17: 000532/23 | D17: ***.103.474-** | E17: HIDELBRANDO JOSE FARKAT DIOGENES | F17: PROFESSOR DO MAGISTERIO SUPERIOR | G17: FUC-0001 | H17: FUC-0001 | I17: 45118 | J17: 45123 | K17: Trata-se da participação em evento científico internacional, a fim de divulgar resultados parciais do doutoramento de Lays Costa, aluna do PPGECAM sob orientação do Prof. Hidelbrando José Farkat Diógenes. | L17: 45118 | M17: 45122 | N17: João Pessoa | O17: Santiago | P17: =VLOOKUP(N17,[1]ID_Cidades!$A$1:$E$5900,2,FALSE) -> 295765 | Q17: =VLOOKUP(O17,[1]ID_Cidades!$A$1:$E$5900,2,FALSE) -> 305806 | R17: =P17*Q17 -> 90446711590 | S17: =VLOOKUP(R17,'[1]GCD base'!$A$1:$M$200,7,FALSE) -> 4701.6614 | T17: Aéreo | U17: Sim | V17: Realizada | W17: SIM | X17: A viagem só pode ser cadastrada nesta data devido ao recurso do PROAP destinado ao pagamento da despesa só foi liberado dia 05/07 e estávamos aguardando, também, a realização do empenho específico. | Y17: 0 | Z17: 0 | AA17: 0 | AB17: 0 | AC17: 0 | AD17: Econômica | AE17: {=_xlfn.IFS(S17<=Constantes!$G$2,"Muito Curta (evitável)",S17<=Constantes!$H$2,"Curta Distância",S17>Constantes!$H$2,"Longa Distância")} -> Longa Distância | AF17: =IFERROR(VLOOKUP(AE17,Constantes!$A$1:$E$5,MATCH(AD17,Constantes!$A$1:$E$1,0),0),"") -> 0.20010828 | AG17: =AF17*S17 -> 940.84139
A18: =COUNTIF($B$2:B18,B18) -> 1 | B18: 18932951 | C18: 000393/23 | D18: ***.778.616-** | E18: PRISCILLA GONTIJO LEITE | F18: PROFESSOR DO MAGISTERIO SUPERIOR | G18: -1 | H18: Sem informação | I18: 45120 | J18: 45128 | K18: Participação da Plenária de Coordenadores do ProfHistória que reúne duas vezes por ano. Esta será a primeira plenária que tem como finalidade de debater e deliberar sobre temas e questões pertinentes ao ProfHistória, propostos pela Comissão Acadêmica Nacional e ou pelas Comissões Acadêmicas Locais. Participação do 32º Simpósio Nacional de História da ANPUH com a comunicação 'Ensino de História Antiga e gamificação para a aprendizagem das formas de governo'. | L18: 45128 | M18: 45128 | N18: São Luís | O18: João Pessoa | P18: =VLOOKUP(N18,[1]ID_Cidades!$A$1:$E$5900,2,FALSE) -> 295771 | Q18: =VLOOKUP(O18,[1]ID_Cidades!$A$1:$E$5900,2,FALSE) -> 295765 | R18: =P18*Q18 -> 87478709815 | S18: =VLOOKUP(R18,'[1]GCD base'!$A$1:$M$200,7,FALSE) -> 1147.347 | T18: Aéreo | U18: Não | V18: Realizada | W18: NÃO | X18: Sem informação | Y18: 2784.3 | Z18: 0 | AA18: 1641.29 | AB18: 0 | AC18: 45083 | AD18: Econômica | AE18: {=_xlfn.IFS(S18<=Constantes!$G$2,"Muito Curta (evitável)",S18<=Constantes!$H$2,"Curta Distância",S18>Constantes!$H$2,"Longa Distância")} -> Curta Distância | AF18: =IFERROR(VLOOKUP(AE18,Constantes!$A$1:$E$5,MATCH(AD18,Constantes!$A$1:$E$1,0),0),"") -> 0.18286935 | AG18: =AF18*S18 -> 209.8146
A19: =COUNTIF($B$2:B19,B19) -> 2 | B19: 18932951 | C19: 000393/23 | D19: ***.778.616-** | E19: PRISCILLA GONTIJO LEITE | F19: PROFESSOR DO MAGISTERIO SUPERIOR | G19: -1 | H19: Sem informação | I19: 45120 | J19: 45128 | K19: Participação da Plenária de Coordenadores do ProfHistória que reúne duas vezes por ano. Esta será a primeira plenária que tem como finalidade de debater e deliberar sobre temas e questões pertinentes ao ProfHistória, propostos pela Comissão Acadêmica Nacional e ou pelas Comissões Acadêmicas Locais. Participação do 32º Simpósio Nacional de História da ANPUH com a comunicação 'Ensino de História Antiga e gamificação para a aprendizagem das formas de governo'. | L19: 45120 | M19: 45128 | N19: João Pessoa | O19: São Luís | P19: =VLOOKUP(N19,[1]ID_Cidades!$A$1:$E$5900,2,FALSE) -> 295765 | Q19: =VLOOKUP(O19,[1]ID_Cidades!$A$1:$E$5900,2,FALSE) -> 295771 | R19: =P19*Q19 -> 87478709815 | S19: =VLOOKUP(R19,'[1]GCD base'!$A$1:$M$200,7,FALSE) -> 1147.347 | T19: Aéreo | U19: Sim | V19: Realizada | W19: NÃO | X19: Sem informação | Y19: 0 | Z19: 0 | AA19: 1643.09 | AB19: 0 | AC19: 45083 | AD19: Econômica | AE19: {=_xlfn.IFS(S19<=Constantes!$G$2,"Muito Curta (evitável)",S19<=Constantes!$H$2,"Curta Distância",S19>Constantes!$H$2,"Longa Distância")} -> Curta Distância | AF19: =IFERROR(VLOOKUP(AE19,Constantes!$A$1:$E$5,MATCH(AD19,Constantes!$A$1:$E$1,0),0),"") -> 0.18286935 | AG19: =AF19*S19 -> 209.8146
A20: =COUNTIF($B$2:B20,B20) -> 1 | B20: 19032444 | C20: 000472/23 | D20: ***.888.244-** | E20: CARLOS ALBERTO OLIVEIRA BONIFACIO JUNIOR | G20: -1 | H20: Sem informação | I20: 45120 | J20: 45125 | K20: PROPOSTO APRESENTARÁ TRABALHO NO 25º FONEPE, QUE OCORRERÁ EM DOURADOS (MS), ENTRE OS DIAS 14,15 E 16 DE JULHO. | L20: 45124 | M20: 45125 | N20: Campo Grande | O20: João Pessoa | P20: =VLOOKUP(N20,[1]ID_Cidades!$A$1:$E$5900,2,FALSE) -> 301205 | Q20: =VLOOKUP(O20,[1]ID_Cidades!$A$1:$E$5900,2,FALSE) -> 295765 | R20: =P20*Q20 -> 89085896825 | S20: =VLOOKUP(R20,'[1]GCD base'!$A$1:$M$200,7,FALSE) -> 2588.8989 | T20: Aéreo | U20: Não | V20: Realizada | W20: SIM | X20: Tendo em vista problemas na emissão da passagem terrestre, a viagem entrou em período de urgência. | Y20: 0 | Z20: 0 | AA20: 932.37 | AB20: 0 | AC20: 45103 | AD20: Econômica | AE20: {=_xlfn.IFS(S20<=Constantes!$G$2,"Muito Curta (evitável)",S20<=Constantes!$H$2,"Curta Distância",S20>Constantes!$H$2,"Longa Distância")} -> Curta Distância | AF20: =IFERROR(VLOOKUP(AE20,Constantes!$A$1:$E$5,MATCH(AD20,Constantes!$A$1:$E$1,0),0),"") -> 0.18286935 | AG20: =AF20*S20 -> 473.43028
A21: =COUNTIF($B$2:B21,B21) -> 2 | B21: 19032444 | C21: 000472/23 | D21: ***.888.244-** | E21: CARLOS ALBERTO OLIVEIRA BONIFACIO JUNIOR | G21: -1 | H21: Sem informação | I21: 45120 | J21: 45125 | K21: PROPOSTO APRESENTARÁ TRABALHO NO 25º FONEPE, QUE OCORRERÁ EM DOURADOS (MS), ENTRE OS DIAS 14,15 E 16 DE JULHO. | L21: 45120 | M21: 45120 | N21: João Pessoa | O21: Campo Grande | P21: =VLOOKUP(N21,[1]ID_Cidades!$A$1:$E$5900,2,FALSE) -> 295765 | Q21: =VLOOKUP(O21,[1]ID_Cidades!$A$1:$E$5900,2,FALSE) -> 301205 | R21: =P21*Q21 -> 89085896825 | S21: =VLOOKUP(R21,'[1]GCD base'!$A$1:$M$200,7,FALSE) -> 2588.8989 | T21: Aéreo | U21: Não | V21: Realizada | W21: SIM | X21: Tendo em vista problemas na emissão da passagem terrestre, a viagem entrou em período de urgência. | Y21: 0 | Z21: 0 | AA21: 1080.09 | AB21: 0 | AC21: 45103 | AD21: Econômica | AE21: {=_xlfn.IFS(S21<=Constantes!$G$2,"Muito Curta (evitável)",S21<=Constantes!$H$2,"Curta Distância",S21>Constantes!$H$2,"Longa Distância")} -> Curta Distância | AF21: =IFERROR(VLOOKUP(AE21,Constantes!$A$1:$E$5,MATCH(AD21,Constantes!$A$1:$E$1,0),0),"") -> 0.18286935 | AG21: =AF21*S21 -> 473.43028
A22: =COUNTIF($B$2:B22,B22) -> 1 | B22: 19098667 | C22: 000601/23 | D22: ***.096.714-** | E22: FRANCISCO HUMBERTO XAVIER JUNIOR | F22: PROFESSOR DO MAGISTERIO SUPERIOR | G22: -1 | H22: Sem informação | I22: 45129 | J22: 45134 | K22: Recebimento do prêmio da 20ª edição do Destaque na Iniciação Científica e Tecnológica entregue pelo presidente do Conselho Nacional de Desenvolvimento Científico e Tecnológico (CNPq), o qual foi concedido a premiação na categoria Iniciação Tecnológica na área das Ciências da Vida para a aluna Ana Flávia Chaves Uchôa, sob minha orientação (anexo I), e será entregue na 75ª Reunião Anual da Sociedade Brasileira para o Progresso da Ciência (SBPC) entre os dias 23 a 29 de julho na Universidade Federal do Paraná (UFPR), em Curitiba | L22: 45134 | M22: 45134 | N22: Curitiba | O22: João Pessoa | P22: =VLOOKUP(N22,[1]ID_Cidades!$A$1:$E$5900,2,FALSE) -> 295780 | Q22: =VLOOKUP(O22,[1]ID_Cidades!$A$1:$E$5900,2,FALSE) -> 295765 | R22: =P22*Q22 -> 87481371700 | S22: =VLOOKUP(R22,'[1]GCD base'!$A$1:$M$200,7,FALSE) -> 2541.6476 | T22: Aéreo | U22: Não | V22: Realizada | W22: SIM | X22: Formulário em anexo | Y22: 1850.97 | Z22: 0 | AA22: 1193.59 | AB22: 0 | AC22: 45125 | AD22: Econômica | AE22: {=_xlfn.IFS(S22<=Constantes!$G$2,"Muito Curta (evitável)",S22<=Constantes!$H$2,"Curta Distância",S22>Constantes!$H$2,"Longa Distância")} -> Curta Distância | AF22: =IFERROR(VLOOKUP(AE22,Constantes!$A$1:$E$5,MATCH(AD22,Constantes!$A$1:$E$1,0),0),"") -> 0.18286935 | AG22: =AF22*S22 -> 464.78946
A23: =COUNTIF($B$2:B23,B23) -> 2 | B23: 19098667 | C23: 000601/23 | D23: ***.096.714-** | E23: FRANCISCO HUMBERTO XAVIER JUNIOR | F23: PROFESSOR DO MAGISTERIO SUPERIOR | G23: -1 | H23: Sem informação | I23: 45129 | J23: 45134 | K23: Recebimento do prêmio da 20ª edição do Destaque na Iniciação Científica e Tecnológica entregue pelo presidente do Conselho Nacional de Desenvolvimento Científico e Tecnológico (CNPq), o qual foi concedido a premiação na categoria Iniciação Tecnológica na área das Ciências da Vida para a aluna Ana Flávia Chaves Uchôa, sob minha orientação (anexo I), e será entregue na 75ª Reunião Anual da Sociedade Brasileira para o Progresso da Ciência (SBPC) entre os dias 23 a 29 de julho na Universidade Federal do Paraná (UFPR), em Curitiba | L23: 45129 | M23: 45134 | N23: João Pessoa | O23: Curitiba | P23: =VLOOKUP(N23,[1]ID_Cidades!$A$1:$E$5900,2,FALSE) -> 295765 | Q23: =VLOOKUP(O23,[1]ID_Cidades!$A$1:$E$5900,2,FALSE) -> 295780 | R23: =P23*Q23 -> 87481371700 | S23: =VLOOKUP(R23,'[1]GCD base'!$A$1:$M$200,7,FALSE) -> 2541.6476 | T23: Aéreo | U23: Sim | V23: Realizada | W23: SIM | X23: Formulário em anexo | Y23: 0 | Z23: 0 | AA23: 1466.89 | AB23: 0 | AC23: 45125 | AD23: Econômica | AE23: {=_xlfn.IFS(S23<=Constantes!$G$2,"Muito Curta (evitável)",S23<=Constantes!$H$2,"Curta Distância",S23>Constantes!$H$2,"Longa Distância")} -> Curta Distância | AF23: =IFERROR(VLOOKUP(AE23,Constantes!$A$1:$E$5,MATCH(AD23,Constantes!$A$1:$E$1,0),0),"") -> 0.18286935 | AG23: =AF23*S23 -> 464.78946
A24: =COUNTIF($B$2:B24,B24) -> 1 | B24: 18973156 | C24: 000407/23 | D24: ***.961.302-** | E24: MARCIA CRISTINA SILVA PAIXAO | F24: PROFESSOR DO MAGISTERIO SUPERIOR | G24: -1 | H24: Sem informação | I24: 45130 | J24: 45135 | K24: Participação do Congresso Nacional da SOBER - Sociedade Brasileira de Economia, Administração e Sociologia Rural como apresentadora de trabalhos, caso o primeiro autor não possa comparecer ao evento. ? Participação do evento como um todo na condição de congressista. Participação da Assembleia Geral da SOBER como componente do seu Conselho Fiscal. | L24: 45130 | M24: 45135 | N24: João Pessoa | O24: Piracicaba | P24: =VLOOKUP(N24,[1]ID_Cidades!$A$1:$E$5900,2,FALSE) -> 295765 | Q24: =VLOOKUP(O24,[1]ID_Cidades!$A$1:$E$5900,2,FALSE) -> 303909 | R24: =P24*Q24 -> 89885645385 | S24: =VLOOKUP(R24,'[1]GCD base'!$A$1:$M$200,7,FALSE) -> 2199.1675 | T24: Aéreo | U24: Sim | V24: Realizada | W24: NÃO | X24: Sem informação | Y24: 1600.4 | Z24: 0 | AA24: 1346.02 | AB24: 0 | AC24: 45083 | AD24: Econômica | AE24: {=_xlfn.IFS(S24<=Constantes!$G$2,"Muito Curta (evitável)",S24<=Constantes!$H$2,"Curta Distância",S24>Constantes!$H$2,"Longa Distância")} -> Curta Distância | AF24: =IFERROR(VLOOKUP(AE24,Constantes!$A$1:$E$5,MATCH(AD24,Constantes!$A$1:$E$1,0),0),"") -> 0.18286935 | AG24: =AF24*S24 -> 402.16035
A25: =COUNTIF($B$2:B25,B25) -> 2 | B25: 18973156 | C25: 000407/23 | D25: ***.961.302-** | E25: MARCIA CRISTINA SILVA PAIXAO | F25: PROFESSOR DO MAGISTERIO SUPERIOR | G25: -1 | H25: Sem informação | I25: 45130 | J25: 45135 | K25: Participação do Congresso Nacional da SOBER - Sociedade Brasileira de Economia, Administração e Sociologia Rural como apresentadora de trabalhos, caso o primeiro autor não possa comparecer ao evento. ? Participação do evento como um todo na condição de congressista. Participação da Assembleia Geral da SOBER como componente do seu Conselho Fiscal. | L25: 45135 | M25: 45135 | N25: Piracicaba | O25: João Pessoa | P25: =VLOOKUP(N25,[1]ID_Cidades!$A$1:$E$5900,2,FALSE) -> 303909 | Q25: =VLOOKUP(O25,[1]ID_Cidades!$A$1:$E$5900,2,FALSE) -> 295765 | R25: =P25*Q25 -> 89885645385 | S25: =VLOOKUP(R25,'[1]GCD base'!$A$1:$M$200,7,FALSE) -> 2199.1675 | T25: Aéreo | U25: Não | V25: Realizada | W25: NÃO | X25: Sem informação | Y25: 0 | Z25: 0 | AA25: 1485.59 | AB25: 0 | AC25: 45083 | AD25: Econômica | AE25: {=_xlfn.IFS(S25<=Constantes!$G$2,"Muito Curta (evitável)",S25<=Constantes!$H$2,"Curta Distância",S25>Constantes!$H$2,"Longa Distância")} -> Curta Distância | AF25: =IFERROR(VLOOKUP(AE25,Constantes!$A$1:$E$5,MATCH(AD25,Constantes!$A$1:$E$1,0),0),"") -> 0.18286935 | AG25: =AF25*S25 -> 402.16035
A26: =COUNTIF($B$2:B26,B26) -> 1 | B26: 19040494 | C26: 000477/23 | D26: ***.840.844-** | E26: HEMILIO FERNANDES CAMPOS COELHO | F26: PROFESSOR DO MAGISTERIO SUPERIOR | G26: FG-0001 | H26: FG-0001 | I26: 45130 | J26: 45136 | K26: Participação do evento científico 67ª Reunião Anual da Região Brasileira da Sociedade Internacional de Biometria (RBras) e 20º Simpósio de Estatística Aplicada à Experimentação Agronômica (SEAGRO) que serão realizados no Centro de Eventos e Convenções do Aurora Shopping na cidade de Londrina. | L26: 45130 | M26: 45136 | N26: João Pessoa | O26: Londrina | P26: =VLOOKUP(N26,[1]ID_Cidades!$A$1:$E$5900,2,FALSE) -> 295765 | Q26: =VLOOKUP(O26,[1]ID_Cidades!$A$1:$E$5900,2,FALSE) -> 304738 | R26: =P26*Q26 -> 90130834570 | S26: =VLOOKUP(R26,'[1]GCD base'!$A$1:$M$200,7,FALSE) -> 2496.4116 | T26: Aéreo | U26: Sim | V26: Realizada | W26: NÃO | X26: Sem informação | Y26: 1901.3 | Z26: 0 | AA26: 1788.29 | AB26: 0 | AC26: 45106 | AD26: Econômica | AE26: {=_xlfn.IFS(S26<=Constantes!$G$2,"Muito Curta (evitável)",S26<=Constantes!$H$2,"Curta Distância",S26>Constantes!$H$2,"Longa Distância")} -> Curta Distância | AF26: =IFERROR(VLOOKUP(AE26,Constantes!$A$1:$E$5,MATCH(AD26,Constantes!$A$1:$E$1,0),0),"") -> 0.18286935 | AG26: =AF26*S26 -> 456.51717
A27: =COUNTIF($B$2:B27,B27) -> 2 | B27: 19040494 | C27: 000477/23 | D27: ***.840.844-** | E27: HEMILIO FERNANDES CAMPOS COELHO | F27: PROFESSOR DO MAGISTERIO SUPERIOR | G27: FG-0001 | H27: FG-0001 | I27: 45130 | J27: 45136 | K27: Participação do evento científico 67ª Reunião Anual da Região Brasileira da Sociedade Internacional de Biometria (RBras) e 20º Simpósio de Estatística Aplicada à Experimentação Agronômica (SEAGRO) que serão realizados no Centro de Eventos e Convenções do Aurora Shopping na cidade de Londrina. | L27: 45136 | M27: 45136 | N27: Londrina | O27: João Pessoa | P27: =VLOOKUP(N27,[1]ID_Cidades!$A$1:$E$5900,2,FALSE) -> 304738 | Q27: =VLOOKUP(O27,[1]ID_Cidades!$A$1:$E$5900,2,FALSE) -> 295765 | R27: =P27*Q27 -> 90130834570 | S27: =VLOOKUP(R27,'[1]GCD base'!$A$1:$M$200,7,FALSE) -> 2496.4116 | T27: Aéreo | U27: Não | V27: Realizada | W27: NÃO | X27: Sem informação | Y27: 0 | Z27: 0 | AA27: 1232.58 | AB27: 0 | AC27: 45106 | AD27: Econômica | AE27: {=_xlfn.IFS(S27<=Constantes!$G$2,"Muito Curta (evitável)",S27<=Constantes!$H$2,"Curta Distância",S27>Constantes!$H$2,"Longa Distância")} -> Curta Distância | AF27: =IFERROR(VLOOKUP(AE27,Constantes!$A$1:$E$5,MATCH(AD27,Constantes!$A$1:$E$1,0),0),"") -> 0.18286935 | AG27: =AF27*S27 -> 456.51717
A28: =COUNTIF($B$2:B28,B28) -> 1 | B28: 19040802 | C28: 000480/23 | D28: ***.447.734-** | E28: ANA HERMINIA ANDRADE E SILVA | F28: PROFESSOR DO MAGISTERIO SUPERIOR | G28: -1 | H28: Sem informação | I28: 45130 | J28: 45136 | K28: Participação do evento científico 67ª Reunião Anual da Região Brasileira da Sociedade Internacional de Biometria (RBras) e 20º Simpósio de Estatística Aplicada à Experimentação Agronômica (SEAGRO) que serão realizados no Centro de Eventos e Convenções do Aurora Shopping na cidade de Londrina. | L28: 45130 | M28: 45136 | N28: João Pessoa | O28: Londrina | P28: =VLOOKUP(N28,[1]ID_Cidades!$A$1:$E$5900,2,FALSE) -> 295765 | Q28: =VLOOKUP(O28,[1]ID_Cidades!$A$1:$E$5900,2,FALSE) -> 304738 | R28: =P28*Q28 -> 90130834570 | S28: =VLOOKUP(R28,'[1]GCD base'!$A$1:$M$200,7,FALSE) -> 2496.4116 | T28: Aéreo | U28: Sim | V28: Realizada | W28: NÃO | X28: Sem informação | Y28: 1901.3 | Z28: 0 | AA28: 1787.18 | AB28: 0 | AC28: 45104 | AD28: Econômica | AE28: {=_xlfn.IFS(S28<=Constantes!$G$2,"Muito Curta (evitável)",S28<=Constantes!$H$2,"Curta Distância",S28>Constantes!$H$2,"Longa Distância")} -> Curta Distância | AF28: =IFERROR(VLOOKUP(AE28,Constantes!$A$1:$E$5,MATCH(AD28,Constantes!$A$1:$E$1,0),0),"") -> 0.18286935 | AG28: =AF28*S28 -> 456.51717
A29: =COUNTIF($B$2:B29,B29) -> 2 | B29: 19040802 | C29: 000480/23 | D29: ***.447.734-** | E29: ANA HERMINIA ANDRADE E SILVA | F29: PROFESSOR DO MAGISTERIO SUPERIOR | G29: -1 | H29: Sem informação | I29: 45130 | J29: 45136 | K29: Participação do evento científico 67ª Reunião Anual da Região Brasileira da Sociedade Internacional de Biometria (RBras) e 20º Simpósio de Estatística Aplicada à Experimentação Agronômica (SEAGRO) que serão realizados no Centro de Eventos e Convenções do Aurora Shopping na cidade de Londrina. | L29: 45136 | M29: 45136 | N29: Londrina | O29: João Pessoa | P29: =VLOOKUP(N29,[1]ID_Cidades!$A$1:$E$5900,2,FALSE) -> 304738 | Q29: =VLOOKUP(O29,[1]ID_Cidades!$A$1:$E$5900,2,FALSE) -> 295765 | R29: =P29*Q29 -> 90130834570 | S29: =VLOOKUP(R29,'[1]GCD base'!$A$1:$M$200,7,FALSE) -> 2496.4116 | T29: Aéreo | U29: Não | V29: Realizada | W29: NÃO | X29: Sem informação | Y29: 0 | Z29: 0 | AA29: 1955.79 | AB29: 0 | AC29: 45104 | AD29: Econômica | AE29: {=_xlfn.IFS(S29<=Constantes!$G$2,"Muito Curta (evitável)",S29<=Constantes!$H$2,"Curta Distância",S29>Constantes!$H$2,"Longa Distância")} -> Curta Distância | AF29: =IFERROR(VLOOKUP(AE29,Constantes!$A$1:$E$5,MATCH(AD29,Constantes!$A$1:$E$1,0),0),"") -> 0.18286935 | AG29: =AF29*S29 -> 456.51717
A30: =COUNTIF($B$2:B30,B30) -> 1 | B30: 19045645 | C30: 000488/23 | D30: ***.260.334-** | E30: EVERLANE SUANE DE ARAUJO DA SILVA | F30: PROFESSOR DO MAGISTERIO SUPERIOR | G30: -1 | H30: Sem informação | I30: 45130 | J30: 45136 | K30: Participação e apresentação em evento científico 67ª Reunião Anual da Região Brasileira da Sociedade Internacional de Biometria (RBras) e 20º Simpósio de Estatística Aplicada à Experimentação Agronômica (SEAGRO) que serão realizados no Centro de Eventos e Convenções do Aurora Shopping na cidade de Londrina. | L30: 45136 | M30: 45136 | N30: Londrina | O30: João Pessoa | P30: =VLOOKUP(N30,[1]ID_Cidades!$A$1:$E$5900,2,FALSE) -> 304738 | Q30: =VLOOKUP(O30,[1]ID_Cidades!$A$1:$E$5900,2,FALSE) -> 295765 | R30: =P30*Q30 -> 90130834570 | S30: =VLOOKUP(R30,'[1]GCD base'!$A$1:$M$200,7,FALSE) -> 2496.4116 | T30: Aéreo | U30: Não | V30: Realizada | W30: NÃO | X30: Sem informação | Y30: 1901.3 | Z30: 0 | AA30: 1232.58 | AB30: 0 | AC30: 45106 | AD30: Econômica | AE30: {=_xlfn.IFS(S30<=Constantes!$G$2,"Muito Curta (evitável)",S30<=Constantes!$H$2,"Curta Distância",S30>Constantes!$H$2,"Longa Distância")} -> Curta Distância | AF30: =IFERROR(VLOOKUP(AE30,Constantes!$A$1:$E$5,MATCH(AD30,Constantes!$A$1:$E$1,0),0),"") -> 0.18286935 | AG30: =AF30*S30 -> 456.51717
A31: =COUNTIF($B$2:B31,B31) -> 2 | B31: 19045645 | C31: 000488/23 | D31: ***.260.334-** | E31: EVERLANE SUANE DE ARAUJO DA SILVA | F31: PROFESSOR DO MAGISTERIO SUPERIOR | G31: -1 | H31: Sem informação | I31: 45130 | J31: 45136 | K31: Participação e apresentação em evento científico 67ª Reunião Anual da Região Brasileira da Sociedade Internacional de Biometria (RBras) e 20º Simpósio de Estatística Aplicada à Experimentação Agronômica (SEAGRO) que serão realizados no Centro de Eventos e Convenções do Aurora Shopping na cidade de Londrina. | L31: 45130 | M31: 45136 | N31: João Pessoa | O31: Londrina | P31: =VLOOKUP(N31,[1]ID_Cidades!$A$1:$E$5900,2,FALSE) -> 295765 | Q31: =VLOOKUP(O31,[1]ID_Cidades!$A$1:$E$5900,2,FALSE) -> 304738 | R31: =P31*Q31 -> 90130834570 | S31: =VLOOKUP(R31,'[1]GCD base'!$A$1:$M$200,7,FALSE) -> 2496.4116 | T31: Aéreo | U31: Sim | V31: Realizada | W31: NÃO | X31: Sem informação | Y31: 0 | Z31: 0 | AA31: 1788.29 | AB31: 0 | AC31: 45106 | AD31: Econômica | AE31: {=_xlfn.IFS(S31<=Constantes!$G$2,"Muito Curta (evitável)",S31<=Constantes!$H$2,"Curta Distância",S31>Constantes!$H$2,"Longa Distância")} -> Curta Distância | AF31: =IFERROR(VLOOKUP(AE31,Constantes!$A$1:$E$5,MATCH(AD31,Constantes!$A$1:$E$1,0),0),"") -> 0.18286935 | AG31: =AF31*S31 -> 456.51717
A32: =COUNTIF($B$2:B32,B32) -> 1 | B32: 19104129 | C32: 000627/23 | D32: ***.919.154-** | E32: SANDRA CRISTINA MORAES DE SOUZA | F32: PROFESSOR ENS BASICO TECN TECNOLOGICO | G32: -1 | H32: Sem informação | I32: 45130 | J32: 45135 | K32: Participar de Oficina na formação na Metodologia Acesso, Permanência e Êxito no Programa Mulheres Mil no período de 24 a 28 de julho de 2023 em Brasília-DF. | L32: 45130 | M32: 45135 | N32: João Pessoa | O32: Brasília | P32: =VLOOKUP(N32,[1]ID_Cidades!$A$1:$E$5900,2,FALSE) -> 295765 | Q32: =VLOOKUP(O32,[1]ID_Cidades!$A$1:$E$5900,2,FALSE) -> 295763 | R32: =P32*Q32 -> 87476343695 | S32: =VLOOKUP(R32,'[1]GCD base'!$A$1:$M$200,7,FALSE) -> 1713.42 | T32: Aéreo | U32: Sim | V32: Realizada | W32: SIM | X32: De acordo com a justificativa anexa. | Y32: 2041.72 | Z32: 0 | AA32: 2113.17 | AB32: 0 | AC32: 45126 | AD32: Econômica | AE32: {=_xlfn.IFS(S32<=Constantes!$G$2,"Muito Curta (evitável)",S32<=Constantes!$H$2,"Curta Distância",S32>Constantes!$H$2,"Longa Distância")} -> Curta Distância | AF32: =IFERROR(VLOOKUP(AE32,Constantes!$A$1:$E$5,MATCH(AD32,Constantes!$A$1:$E$1,0),0),"") -> 0.18286935 | AG32: =AF32*S32 -> 313.33201
A33: =COUNTIF($B$2:B33,B33) -> 2 | B33: 19104129 | C33: 000627/23 | D33: ***.919.154-** | E33: SANDRA CRISTINA MORAES DE SOUZA | F33: PROFESSOR ENS BASICO TECN TECNOLOGICO | G33: -1 | H33: Sem informação | I33: 45130 | J33: 45135 | K33: Participar de Oficina na formação na Metodologia Acesso, Permanência e Êxito no Programa Mulheres Mil no período de 24 a 28 de julho de 2023 em Brasília-DF. | L33: 45135 | M33: 45135 | N33: Brasília | O33: João Pessoa | P33: =VLOOKUP(N33,[1]ID_Cidades!$A$1:$E$5900,2,FALSE) -> 295763 | Q33: =VLOOKUP(O33,[1]ID_Cidades!$A$1:$E$5900,2,FALSE) -> 295765 | R33: =P33*Q33 -> 87476343695 | S33: =VLOOKUP(R33,'[1]GCD base'!$A$1:$M$200,7,FALSE) -> 1713.42 | T33: Aéreo | U33: Não | V33: Realizada | W33: SIM | X33: De acordo com a justificativa anexa. | Y33: 0 | Z33: 0 | AA33: 2569.89 | AB33: 0 | AC33: 45126 | AD33: Econômica | AE33: {=_xlfn.IFS(S33<=Constantes!$G$2,"Muito Curta (evitável)",S33<=Constantes!$H$2,"Curta Distância",S33>Constantes!$H$2,"Longa Distância")} -> Curta Distância | AF33: =IFERROR(VLOOKUP(AE33,Constantes!$A$1:$E$5,MATCH(AD33,Constantes!$A$1:$E$1,0),0),"") -> 0.18286935 | AG33: =AF33*S33 -> 313.33201
... A41: =COUNTIF($B$2:B41,B41) -> 2 | B41: 18924776 | C41: 000329/23 | D41: ***.687.994-** | E41: KARLA KATIUSCIA NOBREGA DE ALMEIDA | F41: PROFESSOR DO MAGISTERIO SUPERIOR | G41: -1 | H41: Sem informação | I41: 45132 | J41: 45135 | K41: Apresentação de 02 artigos científicos de minha co-autoria no 23° USP INTERNATIONAL CONFERENCE ON ACCOUNTING E 20° CONGRESSO USP DE INICIAÇÃO CIENTÍFICA EM CONTABILIDADE - PRESENCIAL | L41: 45135 | M41: 45135 | N41: São Paulo | O41: João Pessoa | P41: =VLOOKUP(N41,[1]ID_Cidades!$A$1:$E$5900,2,FALSE) -> 295779 | Q41: =VLOOKUP(O41,[1]ID_Cidades!$A$1:$E$5900,2,FALSE) -> 295765 | R41: =P41*Q41 -> 87481075935 | S41: =VLOOKUP(R41,'[1]GCD base'!$A$1:$M$200,7,FALSE) -> 2189.9742 | T41: Aéreo | U41: Não | V41: Realizada | W41: NÃO | X41: Sem informação | Y41: 0 | Z41: 0 | AA41: 854.29 | AB41: 0 | AC41: 45065 | AD41: Econômica | AE41: {=_xlfn.IFS(S41<=Constantes!$G$2,"Muito Curta (evitável)",S41<=Constantes!$H$2,"Curta Distância",S41>Constantes!$H$2,"Longa Distância")} -> Curta Distância | AF41: =IFERROR(VLOOKUP(AE41,Constantes!$A$1:$E$5,MATCH(AD41,Constantes!$A$1:$E$1,0),0),"") -> 0.18286935 | AG41: =AF41*S41 -> 400.47918
A42: =COUNTIF($B$2:B42,B42) -> 1 | B42: 18940972 | C42: 000348/23 | D42: ***.834.974-** | E42: EDSON FERREIRA DE ARAUJO | G42: -1 | H42: Sem informação | I42: 45132 | J42: 45136 | K42: PROPOSTO APRESENTARÁ TRABALHO NO 20º CONGRESSO USP DE INICIAÇÃO CIENTÍFICA EM CONTABILIDADE, QUE OCORRERÁ EM SÃO PAULO, ENTRE 26 E 28 DE JULHO DE 2023. | L42: 45136 | M42: 45136 | N42: São Paulo | O42: João Pessoa | P42: =VLOOKUP(N42,[1]ID_Cidades!$A$1:$E$5900,2,FALSE) -> 295779 | Q42: =VLOOKUP(O42,[1]ID_Cidades!$A$1:$E$5900,2,FALSE) -> 295765 | R42: =P42*Q42 -> 87481075935 | S42: =VLOOKUP(R42,'[1]GCD base'!$A$1:$M$200,7,FALSE) -> 2189.9742 | T42: Aéreo | U42: Não | V42: Realizada | W42: NÃO | X42: Sem informação | Y42: 0 | Z42: 0 | AA42: 747.39 | AB42: 0 | AC42: 45071 | AD42: Econômica | AE42: {=_xlfn.IFS(S42<=Constantes!$G$2,"Muito Curta (evitável)",S42<=Constantes!$H$2,"Curta Distância",S42>Constantes!$H$2,"Longa Distância")} -> Curta Distância | AF42: =IFERROR(VLOOKUP(AE42,Constantes!$A$1:$E$5,MATCH(AD42,Constantes!$A$1:$E$1,0),0),"") -> 0.18286935 | AG42: =AF42*S42 -> 400.47918
A43: =COUNTIF($B$2:B43,B43) -> 2 | B43: 18940972 | C43: 000348/23 | D43: ***.834.974-** | E43: EDSON FERREIRA DE ARAUJO | G43: -1 | H43: Sem informação | I43: 45132 | J43: 45136 | K43: PROPOSTO APRESENTARÁ TRABALHO NO 20º CONGRESSO USP DE INICIAÇÃO CIENTÍFICA EM CONTABILIDADE, QUE OCORRERÁ EM SÃO PAULO, ENTRE 26 E 28 DE JULHO DE 2023. | L43: 45132 | M43: 45136 | N43: João Pessoa | O43: São Paulo | P43: =VLOOKUP(N43,[1]ID_Cidades!$A$1:$E$5900,2,FALSE) -> 295765 | Q43: =VLOOKUP(O43,[1]ID_Cidades!$A$1:$E$5900,2,FALSE) -> 295779 | R43: =P43*Q43 -> 87481075935 | S43: =VLOOKUP(R43,'[1]GCD base'!$A$1:$M$200,7,FALSE) -> 2189.9742 | T43: Aéreo | U43: Sim | V43: Realizada | W43: NÃO | X43: Sem informação | Y43: 0 | Z43: 0 | AA43: 731.93 | AB43: 0 | AC43: 45071 | AD43: Econômica | AE43: {=_xlfn.IFS(S43<=Constantes!$G$2,"Muito Curta (evitável)",S43<=Constantes!$H$2,"Curta Distância",S43>Constantes!$H$2,"Longa Distância")} -> Curta Distância | AF43: =IFERROR(VLOOKUP(AE43,Constantes!$A$1:$E$5,MATCH(AD43,Constantes!$A$1:$E$1,0),0),"") -> 0.18286935 | AG43: =AF43*S43 -> 400.47918
A44: =COUNTIF($B$2:B44,B44) -> 1 | B44: 19006789 | C44: 000546/23 | D44: ***.219.784-** | E44: WENNER GLAUCIO LOPES LUCENA | F44: PROFESSOR DO MAGISTERIO SUPERIOR | G44: FUC-0001 | H44: FUC-0001 | I44: 45132 | J44: 45136 | K44: Participação com aprovação de artigo científico no USP Internacional Conference in Accounting da Universidade de São Paulo - USP que será realizado nos dias 26 a 28 de julho de 2023. | L44: 45132 | M44: 45135 | N44: João Pessoa | O44: São Paulo | P44: =VLOOKUP(N44,[1]ID_Cidades!$A$1:$E$5900,2,FALSE) -> 295765 | Q44: =VLOOKUP(O44,[1]ID_Cidades!$A$1:$E$5900,2,FALSE) -> 295779 | R44: =P44*Q44 -> 87481075935 | S44: =VLOOKUP(R44,'[1]GCD base'!$A$1:$M$200,7,FALSE) -> 2189.9742 | T44: Aéreo | U44: Sim | V44: Realizada | W44: NÃO | X44: Sem informação | Y44: 1690.49 | Z44: 0 | AA44: 1305.09 | AB44: 0 | AC44: 45117 | AD44: Econômica | AE44: {=_xlfn.IFS(S44<=Constantes!$G$2,"Muito Curta (evitável)",S44<=Constantes!$H$2,"Curta Distância",S44>Constantes!$H$2,"Longa Distância")} -> Curta Distância | AF44: =IFERROR(VLOOKUP(AE44,Constantes!$A$1:$E$5,MATCH(AD44,Constantes!$A$1:$E$1,0),0),"") -> 0.18286935 | AG44: =AF44*S44 -> 400.47918
A45: =COUNTIF($B$2:B45,B45) -> 2 | B45: 19006789 | C45: 000546/23 | D45: ***.219.784-** | E45: WENNER GLAUCIO LOPES LUCENA | F45: PROFESSOR DO MAGISTERIO SUPERIOR | G45: FUC-0001 | H45: FUC-0001 | I45: 45132 | J45: 45136 | K45: Participação com aprovação de artigo científico no USP Internacional Conference in Accounting da Universidade de São Paulo - USP que será realizado nos dias 26 a 28 de julho de 2023. | L45: 45135 | M45: 45136 | N45: São Paulo | O45: João Pessoa | P45: =VLOOKUP(N45,[1]ID_Cidades!$A$1:$E$5900,2,FALSE) -> 295779 | Q45: =VLOOKUP(O45,[1]ID_Cidades!$A$1:$E$5900,2,FALSE) -> 295765 | R45: =P45*Q45 -> 87481075935 | S45: =VLOOKUP(R45,'[1]GCD base'!$A$1:$M$200,7,FALSE) -> 2189.9742 | T45: Aéreo | U45: Não | V45: Realizada | W45: NÃO | X45: Sem informação | Y45: 0 | Z45: 0 | AA45: 798.83 | AB45: 0 | AC45: 45117 | AD45: Econômica | AE45: {=_xlfn.IFS(S45<=Constantes!$G$2,"Muito Curta (evitável)",S45<=Constantes!$H$2,"Curta Distância",S45>Constantes!$H$2,"Longa Distância")} -> Curta Distância | AF45: =IFERROR(VLOOKUP(AE45,Constantes!$A$1:$E$5,MATCH(AD45,Constantes!$A$1:$E$1,0),0),"") -> 0.18286935 | AG45: =AF45*S45 -> 400.47918
A46: =COUNTIF($B$2:B46,B46) -> 1 | B46: 19052755 | C46: 000545/23 | D46: ***.591.764-** | E46: ROBERIO DANTAS DE FRANCA | F46: PROFESSOR DO MAGISTERIO SUPERIOR | G46: FUC-0001 | H46: FUC-0001 | I46: 45132 | J46: 45136 | K46: Participação no evento USP Internacional Conference in Accounting da Universidade de São Paulo - USP que será realizado nos dias 26 a 28 de julho de 2023, em São Paulo-SP. | L46: 45132 | M46: 45135 | N46: João Pessoa | O46: São Paulo | P46: =VLOOKUP(N46,[1]ID_Cidades!$A$1:$E$5900,2,FALSE) -> 295765 | Q46: =VLOOKUP(O46,[1]ID_Cidades!$A$1:$E$5900,2,FALSE) -> 295779 | R46: =P46*Q46 -> 87481075935 | S46: =VLOOKUP(R46,'[1]GCD base'!$A$1:$M$200,7,FALSE) -> 2189.9742 | T46: Aéreo | U46: Sim | V46: Realizada | W46: NÃO | X46: Sem informação | Y46: 1690.49 | Z46: 0 | AA46: 1305.09 | AB46: 0 | AC46: 45117 | AD46: Econômica | AE46: {=_xlfn.IFS(S46<=Constantes!$G$2,"Muito Curta (evitável)",S46<=Constantes!$H$2,"Curta Distância",S46>Constantes!$H$2,"Longa Distância")} -> Curta Distância | AF46: =IFERROR(VLOOKUP(AE46,Constantes!$A$1:$E$5,MATCH(AD46,Constantes!$A$1:$E$1,0),0),"") -> 0.18286935 | AG46: =AF46*S46 -> 400.47918
A47: =COUNTIF($B$2:B47,B47) -> 2 | B47: 19052755 | C47: 000545/23 | D47: ***.591.764-** | E47: ROBERIO DANTAS DE FRANCA | F47: PROFESSOR DO MAGISTERIO SUPERIOR | G47: FUC-0001 | H47: FUC-0001 | I47: 45132 | J47: 45136 | K47: Participação no evento USP Internacional Conference in Accounting da Universidade de São Paulo - USP que será realizado nos dias 26 a 28 de julho de 2023, em São Paulo-SP. | L47: 45135 | M47: 45136 | N47: São Paulo | O47: João Pessoa | P47: =VLOOKUP(N47,[1]ID_Cidades!$A$1:$E$5900,2,FALSE) -> 295779 | Q47: =VLOOKUP(O47,[1]ID_Cidades!$A$1:$E$5900,2,FALSE) -> 295765 | R47: =P47*Q47 -> 87481075935 | S47: =VLOOKUP(R47,'[1]GCD base'!$A$1:$M$200,7,FALSE) -> 2189.9742 | T47: Aéreo | U47: Não | V47: Realizada | W47: NÃO | X47: Sem informação | Y47: 0 | Z47: 0 | AA47: 798.83 | AB47: 0 | AC47: 45117 | AD47: Econômica | AE47: {=_xlfn.IFS(S47<=Constantes!$G$2,"Muito Curta (evitável)",S47<=Constantes!$H$2,"Curta Distância",S47>Constantes!$H$2,"Longa Distância")} -> Curta Distância | AF47: =IFERROR(VLOOKUP(AE47,Constantes!$A$1:$E$5,MATCH(AD47,Constantes!$A$1:$E$1,0),0),"") -> 0.18286935 | AG47: =AF47*S47 -> 400.47918
...

Sheet Entrada Lvl 5-4 qt
A1: aux | B1: {=_xlfn.UNIQUE(Entradas!B1:B823)} -> Identificador do processo de viagem | C1: Número da Proposta (PCDP) | D1: CPF viajante | E1: Nome | F1: Cargo | G1: Função | H1: Descrição Função | I1: Período - Data de início | J1: Período - Data de fim | K1: Motivo | L1: Distância (km) | M1: Meio de transporte | N1: Missao? | O1: Situação | P1: Viagem Urgente | Q1: Justificativa Urgência Viagem | R1: Valor diárias | S1: Valor outros gastos | T1: Valor da passagem | U1: Taxa de serviço | V1: Data da emissão/compra | W1: Dias de viagem | X1: Classe | Y1: Voo com Escala | Z1: Custo da passagem | AA1: Outros custos | AB1: Motivo da Viagem | AC1: Vínculo Institucional | AD1: dsh, dmh ou dlh | AE1: Viagem Urgente sem justificativa | AF1: Emissões | AG1: ED1.1.1 | AH1: ED1.1.2 | AI1: ED1.1.3 | AJ1: ED1.1 | AK1: ED1.2 | AL1: ED2.1 | AM1: ED2.2 | AN1: ED2.3.1 | AO1: ED2.3.2 | AP1: ED2.3.3 | AQ1: ED2.3 | AR1: ED2.4 | AS1: Tb | AT1: ED2.5 | AU1: ED3.1 | AV1: ED3.2 | AW1: ED3.3 | AX1: DF1.4 | AY1: DF1.5 | AZ1: DF2.1.1 | BA1: DF2.1.2 | BB1: DF2.1.3 | BC1: DF2.1.4 | BD1: DF2.1
A2: =_xlfn.XLOOKUP(B2,Entradas!B:B,Entradas!A:A,,0,-1) -> 2 | B2: 19001658 | C2: =_xlfn.XLOOKUP($B2,Entradas!$B:$B,Entradas!C:C,,0,1) -> 000450/23 | D2: =_xlfn.XLOOKUP($B2,Entradas!$B:$B,Entradas!D:D,,0,1) -> ***.518.375-** | E2: =_xlfn.XLOOKUP($B2,Entradas!$B:$B,Entradas!E:E,,0,1) -> ANGELA DE OLIVEIRA CARNEIRO | F2: =_xlfn.XLOOKUP($B2,Entradas!$B:$B,Entradas!F:F,,0,1) -> PROFESSOR DO MAGISTERIO SUPERIOR | G2: =_xlfn.XLOOKUP($B2,Entradas!$B:$B,Entradas!G:G,,0,1) -> -1 | H2: =_xlfn.XLOOKUP($B2,Entradas!$B:$B,Entradas!H:H,,0,1) -> Sem informação | I2: =_xlfn.XLOOKUP($B2,Entradas!$B:$B,Entradas!I:I,,0,1) -> 45109 | J2: =_xlfn.XLOOKUP($B2,Entradas!$B:$B,Entradas!J:J,,0,1) -> 45121 | K2: =_xlfn.XLOOKUP($B2,Entradas!$B:$B,Entradas!K:K,,0,1) -> O PROPOSTO IRÁ PARTICIPAR COMO MEMBRO DE BANCA DE CONCURSO PÚBLICO DO DEPARTAMENTO DE ENFERMAGEM CLÍNICA | L2: =SUMIF(Entradas!$B:$B,'Entrada Lvl 5-4 qt'!$B2,Entradas!S:S) -> 1331.4793 | M2: =_xlfn.XLOOKUP($B2,Entradas!$B:$B,Entradas!T:T,,0,1) -> Aéreo | N2: =_xlfn.XLOOKUP($B2,Entradas!$B:$B,Entradas!U:U,,0,1) -> Sim | O2: =_xlfn.XLOOKUP($B2,Entradas!$B:$B,Entradas!V:V,,0,1) -> Realizada | P2: =_xlfn.XLOOKUP($B2,Entradas!$B:$B,Entradas!W:W,,0,1) -> SIM | Q2: =_xlfn.XLOOKUP($B2,Entradas!$B:$B,Entradas!X:X,,0,1) -> justificativa em anexo. | R2: =SUMIF(Entradas!$B:$B,'Entrada Lvl 5-4 qt'!$B2,Entradas!Y:Y) -> 4058.65 | S2: =SUMIF(Entradas!$B:$B,'Entrada Lvl 5-4 qt'!$B2,Entradas!Z:Z) -> 0 | T2: =SUMIF(Entradas!$B:$B,'Entrada Lvl 5-4 qt'!$B2,Entradas!AA:AA) -> 4880.98 | U2: =SUMIF(Entradas!$B:$B,'Entrada Lvl 5-4 qt'!$B2,Entradas!AB:AB) -> 0 | V2: =_xlfn.XLOOKUP($B2,Entradas!$B:$B,Entradas!AC:AC,,0,1) -> 45097 | W2: =J2-I2 -> 12 | X2: Econômica | Y2: =IF(A2<3,0,1) -> 0 | Z2: =IFERROR(SUM(T2:U2),0) -> 4880.98 | AA2: =IFERROR(SUM(R2:S2),0) -> 4058.65 | AB2: Participação em Banca Avaliadora | AC2: Acadêmico | AD2: {=_xlfn.IFS(L2<=Constantes!$G$2,"Muito Curta (evitável)",L2<=Constantes!$H$2,"Curta Distância",L2>Constantes!$H$2,"Longa Distância")} -> Curta Distância | AE2: =IF(P2="SIM",IF(Q2="Sem Informação","SIM","NÃO"),"NÃO") -> NÃO | AF2: =SUMIF(Entradas!$B:$B,'Entrada Lvl 5-4 qt'!$B2,Entradas!$AG:$AG) -> 243.48676 | AG2: =SUMIF($AD:$AD,"Muito Curta (evitável)",$AF:$AF) -> 805.86647 | AH2: =SUMIF($AD:$AD,"Curta Distância",$AF:$AF) -> 103690.82 | AI2: =SUMIF($AD:$AD,"Longa Distância",$AF:$AF) -> 194561.12 | AJ2: =SUM(AG2:AI2) -> 299057.81 | AK2: =IFERROR(AJ2/AQ2,0) -> 722.36185 | AL2: =SUM(L:L) -> 1610128.8 | AM2: =AL2/AQ2 -> 3889.1999 | AN2: =COUNTIF($AD:$AD,"Muito Curta (evitável)") -> 6 | AO2: =COUNTIF($AD:$AD,"Curta Distância") -> 204 | AP2: =COUNTIF($AD:$AD,"Longa Distância") -> 204 | AQ2: =SUM(AN2:AP2) -> 414 | AR2: =SUM(Y:Y)/AQ2 -> 0.0072463768 | AS2: =COUNTIF(X:X,"Econômica") -> 414 | AT2: =AS2/AQ2 -> 1 | AU2: =SUM(Z:Z) -> 1150238 | AV2: =SUM(AA:AA) -> 547335.04 | AW2: =SUM(AU2:AV2)/AQ2 -> 4100.418 | AX2: =(SUM((COUNTIF(W:W,"<"&2)),COUNTIF(AD:AD,"Muito Curta (evitável)")))/AQ2 -> 0.031400966 | AY2: =COUNTIFS(P:P,"SIM",Q:Q,"Sem informação")/AS2 -> 0 | AZ2: =(COUNTIF($AC:$AC,"Servidor"))/AQ2 -> 0.31884058 | BA2: =COUNTIF($AC:$AC,"Acadêmico")/AQ2 -> 0.42995169 | BB2: =COUNTIF($AC:$AC,"Discente")/AQ2 -> 0.15217391 | BC2: =COUNTIF($AC:$AC,"Externo")/AQ2 -> 0.099033816 | BD2: =SUM(AZ2:BC2) -> 1
A3: =_xlfn.XLOOKUP(B3,Entradas!B:B,Entradas!A:A,,0,-1) -> 2 | B3: 19016293 | C3: =_xlfn.XLOOKUP($B3,Entradas!$B:$B,Entradas!C:C,,0,1) -> 000452/23 | D3: =_xlfn.XLOOKUP($B3,Entradas!$B:$B,Entradas!D:D,,0,1) -> ***.187.354-** | E3: =_xlfn.XLOOKUP($B3,Entradas!$B:$B,Entradas!E:E,,0,1) -> MARIA FATIMA DE SOUSA | F3: =_xlfn.XLOOKUP($B3,Entradas!$B:$B,Entradas!F:F,,0,1) -> PROFESSOR DO MAGISTERIO SUPERIOR | G3: =_xlfn.XLOOKUP($B3,Entradas!$B:$B,Entradas!G:G,,0,1) -> -1 | H3: =_xlfn.XLOOKUP($B3,Entradas!$B:$B,Entradas!H:H,,0,1) -> Sem informação | I3: =_xlfn.XLOOKUP($B3,Entradas!$B:$B,Entradas!I:I,,0,1) -> 45109 | J3: =_xlfn.XLOOKUP($B3,Entradas!$B:$B,Entradas!J:J,,0,1) -> 45122 | K3: =_xlfn.XLOOKUP($B3,Entradas!$B:$B,Entradas!K:K,,0,1) -> O PROPOSTO IRÁ PARTICIPAR COMO MEMBRO DE BANCA DE CONCURSO PÚBLICO DO DEPARTAMENTO DE ENFERMAGEM CLÍNICA | L3: =SUMIF(Entradas!$B:$B,'Entrada Lvl 5-4 qt'!$B3,Entradas!S:S) -> 3426.84 | M3: =_xlfn.XLOOKUP($B3,Entradas!$B:$B,Entradas!T:T,,0,1) -> Aéreo | N3: =_xlfn.XLOOKUP($B3,Entradas!$B:$B,Entradas!U:U,,0,1) -> Não | O3: =_xlfn.XLOOKUP($B3,Entradas!$B:$B,Entradas!V:V,,0,1) -> Realizada | P3: =_xlfn.XLOOKUP($B3,Entradas!$B:$B,Entradas!W:W,,0,1) -> SIM | Q3: =_xlfn.XLOOKUP($B3,Entradas!$B:$B,Entradas!X:X,,0,1) -> justificativa em anexo. | R3: =SUMIF(Entradas!$B:$B,'Entrada Lvl 5-4 qt'!$B3,Entradas!Y:Y) -> 4399.67 | S3: =SUMIF(Entradas!$B:$B,'Entrada Lvl 5-4 qt'!$B3,Entradas!Z:Z) -> 0 | T3: =SUMIF(Entradas!$B:$B,'Entrada Lvl 5-4 qt'!$B3,Entradas!AA:AA) -> 2590.96 | U3: =SUMIF(Entradas!$B:$B,'Entrada Lvl 5-4 qt'!$B3,Entradas!AB:AB) -> 0 | V3: =_xlfn.XLOOKUP($B3,Entradas!$B:$B,Entradas!AC:AC,,0,1) -> 45097 | W3: =J3-I3 -> 13 | X3: Econômica | Y3: =IF(A3<3,0,1) -> 0 | Z3: =IFERROR(SUM(T3:U3),0) -> 2590.96 | AA3: =IFERROR(SUM(R3:S3),0) -> 4399.67 | AB3: Participação em Banca Avaliadora | AC3: Acadêmico | AD3: {=_xlfn.IFS(L3<=Constantes!$G$2,"Muito Curta (evitável)",L3<=Constantes!$H$2,"Curta Distância",L3>Constantes!$H$2,"Longa Distância")} -> Curta Distância | AE3: =IF(P3="SIM",IF(Q3="Sem Informação","SIM","NÃO"),"NÃO") -> NÃO | AF3: =SUMIF(Entradas!$B:$B,'Entrada Lvl 5-4 qt'!$B3,Entradas!$AG:$AG) -> 626.66402
A4: =_xlfn.XLOOKUP(B4,Entradas!B:B,Entradas!A:A,,0,-1) -> 2 | B4: 19019910 | C4: =_xlfn.XLOOKUP($B4,Entradas!$B:$B,Entradas!C:C,,0,1) -> 000457/23 | D4: =_xlfn.XLOOKUP($B4,Entradas!$B:$B,Entradas!D:D,,0,1) -> ***.105.073-** | E4: =_xlfn.XLOOKUP($B4,Entradas!$B:$B,Entradas!E:E,,0,1) -> ROBERTA MENESES OLIVEIRA | F4: =_xlfn.XLOOKUP($B4,Entradas!$B:$B,Entradas!F:F,,0,1) -> PROFESSOR DO MAGISTERIO SUPERIOR | G4: =_xlfn.XLOOKUP($B4,Entradas!$B:$B,Entradas!G:G,,0,1) -> -1 | H4: =_xlfn.XLOOKUP($B4,Entradas!$B:$B,Entradas!H:H,,0,1) -> Sem informação | I4: =_xlfn.XLOOKUP($B4,Entradas!$B:$B,Entradas!I:I,,0,1) -> 45109 | J4: =_xlfn.XLOOKUP($B4,Entradas!$B:$B,Entradas!J:J,,0,1) -> 45122 | K4: =_xlfn.XLOOKUP($B4,Entradas!$B:$B,Entradas!K:K,,0,1) -> O PROPOSTO IRÁ PARTICIPAR COMO MEMBRO DE BANCA DE CONCURSO PÚBLICO DO DEPARTAMENTO DE ENFERMAGEM CLÍNICA | L4: =SUMIF(Entradas!$B:$B,'Entrada Lvl 5-4 qt'!$B4,Entradas!S:S) -> 1092.4729 | M4: =_xlfn.XLOOKUP($B4,Entradas!$B:$B,Entradas!T:T,,0,1) -> Aéreo | N4: =_xlfn.XLOOKUP($B4,Entradas!$B:$B,Entradas!U:U,,0,1) -> Sim | O4: =_xlfn.XLOOKUP($B4,Entradas!$B:$B,Entradas!V:V,,0,1) -> Realizada | P4: =_xlfn.XLOOKUP($B4,Entradas!$B:$B,Entradas!W:W,,0,1) -> SIM | Q4: =_xlfn.XLOOKUP($B4,Entradas!$B:$B,Entradas!X:X,,0,1) -> justificativa em anexo. | R4: =SUMIF(Entradas!$B:$B,'Entrada Lvl 5-4 qt'!$B4,Entradas!Y:Y) -> 4399.67 | S4: =SUMIF(Entradas!$B:$B,'Entrada Lvl 5-4 qt'!$B4,Entradas!Z:Z) -> 0 | T4: =SUMIF(Entradas!$B:$B,'Entrada Lvl 5-4 qt'!$B4,Entradas!AA:AA) -> 1709.7 | U4: =SUMIF(Entradas!$B:$B,'Entrada Lvl 5-4 qt'!$B4,Entradas!AB:AB) -> 0 | V4: =_xlfn.XLOOKUP($B4,Entradas!$B:$B,Entradas!AC:AC,,0,1) -> 45098 | W4: =J4-I4 -> 13 | X4: Econômica | Y4: =IF(A4<3,0,1) -> 0 | Z4: =IFERROR(SUM(T4:U4),0) -> 1709.7 | AA4: =IFERROR(SUM(R4:S4),0) -> 4399.67 | AB4: Participação em Banca Avaliadora | AC4: Acadêmico | AD4: {=_xlfn.IFS(L4<=Constantes!$G$2,"Muito Curta (evitável)",L4<=Constantes!$H$2,"Curta Distância",L4>Constantes!$H$2,"Longa Distância")} -> Curta Distância | AE4: =IF(P4="SIM",IF(Q4="Sem Informação","SIM","NÃO"),"NÃO") -> NÃO | AF4: =SUMIF(Entradas!$B:$B,'Entrada Lvl 5-4 qt'!$B4,Entradas!$AG:$AG) -> 297.78274
A5: =_xlfn.XLOOKUP(B5,Entradas!B:B,Entradas!A:A,,0,-1) -> 2 | B5: 19041737 | C5: =_xlfn.XLOOKUP($B5,Entradas!$B:$B,Entradas!C:C,,0,1) -> 000481/23-3C | D5: =_xlfn.XLOOKUP($B5,Entradas!$B:$B,Entradas!D:D,,0,1) -> ***.567.773-** | E5: =_xlfn.XLOOKUP($B5,Entradas!$B:$B,Entradas!E:E,,0,1) -> BERLA MOREIRA DE MORAES | F5: =_xlfn.XLOOKUP($B5,Entradas!$B:$B,Entradas!F:F,,0,1) -> PROFESSOR DO MAGISTERIO SUPERIOR | G5: =_xlfn.XLOOKUP($B5,Entradas!$B:$B,Entradas!G:G,,0,1) -> CD-0002 | H5: =_xlfn.XLOOKUP($B5,Entradas!$B:$B,Entradas!H:H,,0,1) -> Cargo Comissionado de Direção | I5: =_xlfn.XLOOKUP($B5,Entradas!$B:$B,Entradas!I:I,,0,1) -> 45110 | J5: =_xlfn.XLOOKUP($B5,Entradas!$B:$B,Entradas!J:J,,0,1) -> 45113 | K5: =_xlfn.XLOOKUP($B5,Entradas!$B:$B,Entradas!K:K,,0,1) -> Participar do I ENCONTRO NACIONAL DE CULTURA & ARTE NAS UNIVERSIDADES FEDERAIS BRASILEIRAS, em Salvador/BA, no período de 03 a 05/07/2023 | L5: =SUMIF(Entradas!$B:$B,'Entrada Lvl 5-4 qt'!$B5,Entradas!S:S) -> 1482.2388 | M5: =_xlfn.XLOOKUP($B5,Entradas!$B:$B,Entradas!T:T,,0,1) -> Aéreo | N5: =_xlfn.XLOOKUP($B5,Entradas!$B:$B,Entradas!U:U,,0,1) -> Sim | O5: =_xlfn.XLOOKUP($B5,Entradas!$B:$B,Entradas!V:V,,0,1) -> Realizada | P5: =_xlfn.XLOOKUP($B5,Entradas!$B:$B,Entradas!W:W,,0,1) -> SIM | Q5: =_xlfn.XLOOKUP($B5,Entradas!$B:$B,Entradas!X:X,,0,1) -> 0 convite para participar do evento chegou fora do prazo, conforme justificativa no formulário de solicitação | R5: =SUMIF(Entradas!$B:$B,'Entrada Lvl 5-4 qt'!$B5,Entradas!Y:Y) -> 1720.73 | S5: =SUMIF(Entradas!$B:$B,'Entrada Lvl 5-4 qt'!$B5,Entradas!Z:Z) -> 0 | T5: =SUMIF(Entradas!$B:$B,'Entrada Lvl 5-4 qt'!$B5,Entradas!AA:AA) -> 3694.45 | U5: =SUMIF(Entradas!$B:$B,'Entrada Lvl 5-4 qt'!$B5,Entradas!AB:AB) -> 0 | V5: =_xlfn.XLOOKUP($B5,Entradas!$B:$B,Entradas!AC:AC,,0,1) -> 45104 | W5: =J5-I5 -> 3 | X5: Econômica | Y5: =IF(A5<3,0,1) -> 0 | Z5: =IFERROR(SUM(T5:U5),0) -> 3694.45 | AA5: =IFERROR(SUM(R5:S5),0) -> 1720.73 | AB5: Representação em Evento Institucional | AC5: Servidor | AD5: {=_xlfn.IFS(L5<=Constantes!$G$2,"Muito Curta (evitável)",L5<=Constantes!$H$2,"Curta Distância",L5>Constantes!$H$2,"Longa Distância")} -> Curta Distância | AE5: =IF(P5="SIM",IF(Q5="Sem Informação","SIM","NÃO"),"NÃO") -> NÃO | AF5: =SUMIF(Entradas!$B:$B,'Entrada Lvl 5-4 qt'!$B5,Entradas!$AG:$AG) -> 271.05606
