Workbook
Name _xlchart.v1.0: 'Resultados DF'!$S$2:$S$26
Name _xlchart.v1.1: 'Resultados DF'!$T$1
Name _xlchart.v1.2: 'Resultados DF'!$T$2:$T$26
Name _xlchart.v1.3: 'Resultados DF'!$U$1
Name _xlchart.v1.4: 'Resultados DF'!$U$2:$U$26

Sheet Baseline
A1: Valores Absolutos
A2: Indicador | B2: 2018.1 | C2: 2019.1 | D2: 2020.1 | E2: 2021.1 | F2: 2022.1 | G2: 2023.1
A3: ED1.1 | B3: ='[1]Agregação Lvl 3-1'!C3 | C3: ='[2]Agregação Lvl 3-1'!C3 | D3: ='[3]Agregação Lvl 3-1'!C3 | E3: ='[4]Agregação Lvl 3-1'!C3 | F3: ='[5]Agregação Lvl 3-1'!C3 | G3: ='[6]Agregação Lvl 3-1'!C3
A4: ED1.2 | B4: ='[1]Agregação Lvl 3-1'!C4 | C4: ='[2]Agregação Lvl 3-1'!C4 | D4: ='[3]Agregação Lvl 3-1'!C4 | E4: ='[4]Agregação Lvl 3-1'!C4 | F4: ='[5]Agregação Lvl 3-1'!C4 | G4: ='[6]Agregação Lvl 3-1'!C4
A5: ED2.1 | B5: ='[1]Agregação Lvl 3-1'!C5 | C5: ='[2]Agregação Lvl 3-1'!C5 | D5: ='[3]Agregação Lvl 3-1'!C5 | E5: ='[4]Agregação Lvl 3-1'!C5 | F5: ='[5]Agregação Lvl 3-1'!C5 | G5: ='[6]Agregação Lvl 3-1'!C5
A6: ED2.2 | B6: ='[1]Agregação Lvl 3-1'!C6 | C6: ='[2]Agregação Lvl 3-1'!C6 | D6: ='[3]Agregação Lvl 3-1'!C6 | E6: ='[4]Agregação Lvl 3-1'!C6 | F6: ='[5]Agregação Lvl 3-1'!C6 | G6: ='[6]Agregação Lvl 3-1'!C6
A7: ED2.3 | B7: ='[1]Agregação Lvl 3-1'!C7 | C7: ='[2]Agregação Lvl 3-1'!C7 | D7: ='[3]Agregação Lvl 3-1'!C7 | E7: ='[4]Agregação Lvl 3-1'!C7 | F7: ='[5]Agregação Lvl 3-1'!C7 | G7: ='[6]Agregação Lvl 3-1'!C7 | L7: =(G7-F7)/G7 | M7: =(G7-B7)/G7
A8: ED2.4 | B8: ='[1]Agregação Lvl 3-1'!C8 | C8: ='[2]Agregação Lvl 3-1'!C8 | D8: ='[3]Agregação Lvl 3-1'!C8 | E8: ='[4]Agregação Lvl 3-1'!C8 | F8: ='[5]Agregação Lvl 3-1'!C8 | G8: ='[6]Agregação Lvl 3-1'!C8
A9: ED2.5 | B9: ='[1]Agregação Lvl 3-1'!C9 | C9: ='[2]Agregação Lvl 3-1'!C9 | D9: ='[3]Agregação Lvl 3-1'!C9 | E9: ='[4]Agregação Lvl 3-1'!C9 | F9: ='[5]Agregação Lvl 3-1'!C9 | G9: ='[6]Agregação Lvl 3-1'!C9
A10: ED3.1 | B10: ='[1]Agregação Lvl 3-1'!C10 | C10: ='[2]Agregação Lvl 3-1'!C10 | D10: ='[3]Agregação Lvl 3-1'!C10 | E10: ='[4]Agregação Lvl 3-1'!C10 | F10: ='[5]Agregação Lvl 3-1'!C10 | G10: ='[6]Agregação Lvl 3-1'!C10
A11: ED3.2 | B11: ='[1]Agregação Lvl 3-1'!C11 | C11: ='[2]Agregação Lvl 3-1'!C11 | D11: ='[3]Agregação Lvl 3-1'!C11 | E11: ='[4]Agregação Lvl 3-1'!C11 | F11: ='[5]Agregação Lvl 3-1'!C11 | G11: ='[6]Agregação Lvl 3-1'!C11
A12: ED3.3 | B12: ='[1]Agregação Lvl 3-1'!C12 | C12: ='[2]Agregação Lvl 3-1'!C12 | D12: ='[3]Agregação Lvl 3-1'!C12 | E12: ='[4]Agregação Lvl 3-1'!C12 | F12: ='[5]Agregação Lvl 3-1'!C12 | G12: ='[6]Agregação Lvl 3-1'!C12
A13: DF1.4 | B13: ='[1]Agregação Lvl 3-1'!C13 | C13: ='[2]Agregação Lvl 3-1'!C13 | D13: ='[3]Agregação Lvl 3-1'!C13 | E13: ='[4]Agregação Lvl 3-1'!C13 | F13: ='[5]Agregação Lvl 3-1'!C13 | G13: ='[6]Agregação Lvl 3-1'!C13
A14: DF1.5 | B14: ='[1]Agregação Lvl 3-1'!C14 | C14: ='[2]Agregação Lvl 3-1'!C14 | D14: ='[3]Agregação Lvl 3-1'!C14 | E14: ='[4]Agregação Lvl 3-1'!C14 | F14: ='[5]Agregação Lvl 3-1'!C14 | G14: ='[6]Agregação Lvl 3-1'!C14
A16: Indicador | B16: 2018.2 | C16: 2019.2 | D16: 2020.2 | E16: 2021.2 | F16: 2022.2 | G16: 2023.2
A17: ED1.1 | B17: ='[7]Agregação Lvl 3-1'!C3 | C17: ='[8]Agregação Lvl 3-1'!C3 | D17: ='[9]Agregação Lvl 3-1'!C3 | E17: ='[10]Agregação Lvl 3-1'!C3 | F17: ='[11]Agregação Lvl 3-1'!C3 | G17: ='[12]Agregação Lvl 3-1'!C3
A18: ED1.2 | B18: ='[7]Agregação Lvl 3-1'!C4 | C18: ='[8]Agregação Lvl 3-1'!C4 | D18: ='[9]Agregação Lvl 3-1'!C4 | E18: ='[10]Agregação Lvl 3-1'!C4 | F18: ='[11]Agregação Lvl 3-1'!C4 | G18: ='[12]Agregação Lvl 3-1'!C4
A19: ED2.1 | B19: ='[7]Agregação Lvl 3-1'!C5 | C19: ='[8]Agregação Lvl 3-1'!C5 | D19: ='[9]Agregação Lvl 3-1'!C5 | E19: ='[10]Agregação Lvl 3-1'!C5 | F19: ='[11]Agregação Lvl 3-1'!C5 | G19: ='[12]Agregação Lvl 3-1'!C5
A20: ED2.2 | B20: ='[7]Agregação Lvl 3-1'!C6 | C20: ='[8]Agregação Lvl 3-1'!C6 | D20: ='[9]Agregação Lvl 3-1'!C6 | E20: ='[10]Agregação Lvl 3-1'!C6 | F20: ='[11]Agregação Lvl 3-1'!C6 | G20: ='[12]Agregação Lvl 3-1'!C6
A21: ED2.3 | B21: ='[7]Agregação Lvl 3-1'!C7 | C21: ='[8]Agregação Lvl 3-1'!C7 | D21: ='[9]Agregação Lvl 3-1'!C7 | E21: ='[10]Agregação Lvl 3-1'!C7 | F21: ='[11]Agregação Lvl 3-1'!C7 | G21: ='[12]Agregação Lvl 3-1'!C7 | L21: =(G21-F21)/G21 | M21: =(G21-B21)/G21
A22: ED2.4 | B22: ='[7]Agregação Lvl 3-1'!C8 | C22: ='[8]Agregação Lvl 3-1'!C8 | D22: ='[9]Agregação Lvl 3-1'!C8 | E22: ='[10]Agregação Lvl 3-1'!C8 | F22: ='[11]Agregação Lvl 3-1'!C8 | G22: ='[12]Agregação Lvl 3-1'!C8
A23: ED2.5 | B23: ='[7]Agregação Lvl 3-1'!C9 | C23: ='[8]Agregação Lvl 3-1'!C9 | D23: ='[9]Agregação Lvl 3-1'!C9 | E23: ='[10]Agregação Lvl 3-1'!C9 | F23: ='[11]Agregação Lvl 3-1'!C9 | G23: ='[12]Agregação Lvl 3-1'!C9
A24: ED3.1 | B24: ='[7]Agregação Lvl 3-1'!C10 | C24: ='[8]Agregação Lvl 3-1'!C10*$C$91 | D24: ='[9]Agregação Lvl 3-1'!C10 | E24: ='[10]Agregação Lvl 3-1'!C10 | F24: ='[11]Agregação Lvl 3-1'!C10 | G24: ='[12]Agregação Lvl 3-1'!C10 | L24: =(G24-F24)/G24
A25: ED3.2 | B25: ='[7]Agregação Lvl 3-1'!C11 | C25: ='[8]Agregação Lvl 3-1'!C11*$C$91 | D25: ='[9]Agregação Lvl 3-1'!C11 | E25: ='[10]Agregação Lvl 3-1'!C11 | F25: ='[11]Agregação Lvl 3-1'!C11 | G25: ='[12]Agregação Lvl 3-1'!C11
A26: ED3.3 | B26: ='[7]Agregação Lvl 3-1'!C12 | C26: ='[8]Agregação Lvl 3-1'!C12 | D26: ='[9]Agregação Lvl 3-1'!C12 | E26: ='[10]Agregação Lvl 3-1'!C12 | F26: ='[11]Agregação Lvl 3-1'!C12 | G26: ='[12]Agregação Lvl 3-1'!C12
A27: DF1.4 | B27: ='[7]Agregação Lvl 3-1'!C13 | C27: ='[8]Agregação Lvl 3-1'!C13 | D27: ='[9]Agregação Lvl 3-1'!C13 | E27: ='[10]Agregação Lvl 3-1'!C13 | F27: ='[11]Agregação Lvl 3-1'!C13 | G27: ='[12]Agregação Lvl 3-1'!C13
A28: DF1.5 | B28: ='[7]Agregação Lvl 3-1'!C14 | C28: ='[8]Agregação Lvl 3-1'!C14 | D28: ='[9]Agregação Lvl 3-1'!C14 | E28: ='[10]Agregação Lvl 3-1'!C14 | F28: ='[11]Agregação Lvl 3-1'!C14 | G28: ='[12]Agregação Lvl 3-1'!C14
A30: Correção da inflação para 2022
A31: Indicador | B31: 2018.1 | C31: 2019.1 | D31: 2020.1 | E31: 2021.1 | F31: 2022.1 | G31: MM (18.1-19.1)
A32: ED1.1 | B32: =B3 | C32: =C3 | D32: =D3 | E32: =E3 | F32: =F3 | G32: =AVERAGE(B32,C32)
A33: ED1.2 | B33: =B4 | C33: =C4 | D33: =D4 | E33: =E4 | F33: =F4 | G33: =AVERAGE(B33,C33)
A34: ED2.1 | B34: =B5 | C34: =C5 | D34: =D5 | E34: =E5 | F34: =F5 | G34: =AVERAGE(B34,C34)
A35: ED2.2 | B35: =B6 | C35: =C6 | D35: =D6 | E35: =E6 | F35: =F6 | G35: =AVERAGE(B35,C35)
A36: ED2.3 | B36: =B7 | C36: =C7 | D36: =D7 | E36: =E7 | F36: =F7 | G36: =AVERAGE(B36,C36)
A37: ED2.4 | B37: =B8 | C37: =C8 | D37: =D8 | E37: =E8 | F37: =F8 | G37: =AVERAGE(B37,C37)
A38: ED2.5 | B38: =B9 | C38: =C9 | D38: =D9 | E38: =E9 | F38: =F9 | G38: =AVERAGE(B38,C38)
A39: ED3.1 | B39: =B10*B$91 | C39: =C10*C$91 | D39: =D10*D$91 | E39: =E10*E$91 | F39: =F10*F$91 | G39: =AVERAGE(B39,C39)
A40: ED3.2 | B40: =B11*B$91 | C40: =C11*C$91 | D40: =D11*D$91 | E40: =E11*E$91 | F40: =F11*F$91 | G40: =AVERAGE(B40,C40)
A41: ED3.3 | B41: =B12*B$91 | C41: =C12*C$91 | D41: =D12*D$91 | E41: =E12*E$91 | F41: =F12*F$91 | G41: =AVERAGE(B41,C41)
A42: DF1.4 | B42: =B13 | C42: =C13 | D42: =D13 | E42: =E13 | F42: =F13 | G42: =AVERAGE(B42,C42)
...

Sheet Resultados Aplicação do Modelo
A1: Descrição | B1: Indicador | C1: Baseline (18.1 - 21.1) | D1: Dados (2022.1) | E1: Score (2022.1) | F1: Baseline (18.2 - 21.2) | G1: Dados (2022.2) | H1: Score (2022.2) | I1: Baseline (19.1 - 22.1) | J1: Dados (2023.1) | K1: Score (2023.1) | L1: Baseline (19.2 - 22.2) | M1: Dados (2023.2) | N1: Score (2023.2)
A2: Total de emissões (kgCO2eq) | B2: ED1.1 | C2: ='[5]Agregação Lvl 3-1'!B3 | D2: ='[5]Agregação Lvl 3-1'!C3 | E2: ='[5]Agregação Lvl 3-1'!E3 | F2: ='[11]Agregação Lvl 3-1'!B3 | G2: ='[11]Agregação Lvl 3-1'!C3 | H2: ='[11]Agregação Lvl 3-1'!E3 | I2: ='[6]Agregação Lvl 3-1'!B3 | J2: ='[6]Agregação Lvl 3-1'!C3 | K2: ='[6]Agregação Lvl 3-1'!E3 | L2: ='[12]Agregação Lvl 3-1'!B3 | M2: ='[12]Agregação Lvl 3-1'!C3 | N2: ='[12]Agregação Lvl 3-1'!E3
A3: Emissão média por viagem (kgCO2eq/trip) | B3: ED1.2 | C3: ='[5]Agregação Lvl 3-1'!B4 | D3: ='[5]Agregação Lvl 3-1'!C4 | E3: ='[5]Agregação Lvl 3-1'!E4 | F3: ='[11]Agregação Lvl 3-1'!B4 | G3: ='[11]Agregação Lvl 3-1'!C4 | H3: ='[11]Agregação Lvl 3-1'!E4 | I3: ='[6]Agregação Lvl 3-1'!B4 | J3: ='[6]Agregação Lvl 3-1'!C4 | K3: ='[6]Agregação Lvl 3-1'!E4 | L3: ='[12]Agregação Lvl 3-1'!B4 | M3: ='[12]Agregação Lvl 3-1'!C4 | N3: ='[12]Agregação Lvl 3-1'!E4
A4: Distância Total percorrida (km) | B4: ED2.1 | C4: ='[5]Agregação Lvl 3-1'!B5 | D4: ='[5]Agregação Lvl 3-1'!C5 | E4: ='[5]Agregação Lvl 3-1'!E5 | F4: ='[11]Agregação Lvl 3-1'!B5 | G4: ='[11]Agregação Lvl 3-1'!C5 | H4: ='[11]Agregação Lvl 3-1'!E5 | I4: ='[6]Agregação Lvl 3-1'!B5 | J4: ='[6]Agregação Lvl 3-1'!C5 | K4: ='[6]Agregação Lvl 3-1'!E5 | L4: ='[12]Agregação Lvl 3-1'!B5 | M4: ='[12]Agregação Lvl 3-1'!C5 | N4: ='[12]Agregação Lvl 3-1'!E5
A5: Distância média por viagem (km/trip) | B5: ED2.2 | C5: ='[5]Agregação Lvl 3-1'!B6 | D5: ='[5]Agregação Lvl 3-1'!C6 | E5: ='[5]Agregação Lvl 3-1'!E6 | F5: ='[11]Agregação Lvl 3-1'!B6 | G5: ='[11]Agregação Lvl 3-1'!C6 | H5: ='[11]Agregação Lvl 3-1'!E6 | I5: ='[6]Agregação Lvl 3-1'!B6 | J5: ='[6]Agregação Lvl 3-1'!C6 | K5: ='[6]Agregação Lvl 3-1'!E6 | L5: ='[12]Agregação Lvl 3-1'!B6 | M5: ='[12]Agregação Lvl 3-1'!C6 | N5: ='[12]Agregação Lvl 3-1'!E6
A6: Número de Viagens (trip) | B6: ED2.3 | C6: ='[5]Agregação Lvl 3-1'!B7 | D6: ='[5]Agregação Lvl 3-1'!C7 | E6: ='[5]Agregação Lvl 3-1'!E7 | F6: ='[11]Agregação Lvl 3-1'!B7 | G6: ='[11]Agregação Lvl 3-1'!C7 | H6: ='[11]Agregação Lvl 3-1'!E7 | I6: ='[6]Agregação Lvl 3-1'!B7 | J6: ='[6]Agregação Lvl 3-1'!C7 | K6: ='[6]Agregação Lvl 3-1'!E7 | L6: ='[12]Agregação Lvl 3-1'!B7 | M6: ='[12]Agregação Lvl 3-1'!C7 | N6: ='[12]Agregação Lvl 3-1'!E7
A7: Taxa de voos com escala | B7: ED2.4 | C7: ='[5]Agregação Lvl 3-1'!B8 | D7: ='[5]Agregação Lvl 3-1'!C8 | E7: ='[5]Agregação Lvl 3-1'!E8 | F7: ='[11]Agregação Lvl 3-1'!B8 | G7: ='[11]Agregação Lvl 3-1'!C8 | H7: ='[11]Agregação Lvl 3-1'!E8 | I7: ='[6]Agregação Lvl 3-1'!B8 | J7: ='[6]Agregação Lvl 3-1'!C8 | K7: ='[6]Agregação Lvl 3-1'!E8 | L7: ='[12]Agregação Lvl 3-1'!B8 | M7: ='[12]Agregação Lvl 3-1'!C8 | N7: ='[12]Agregação Lvl 3-1'!E8
A8: Taxa de viagens em classe econômica | B8: ED2.5 | C8: ='[5]Agregação Lvl 3-1'!B9 | D8: ='[5]Agregação Lvl 3-1'!C9 | E8: ='[5]Agregação Lvl 3-1'!E9 | F8: ='[11]Agregação Lvl 3-1'!B9 | G8: ='[11]Agregação Lvl 3-1'!C9 | H8: ='[11]Agregação Lvl 3-1'!E9 | I8: ='[6]Agregação Lvl 3-1'!B9 | J8: ='[6]Agregação Lvl 3-1'!C9 | K8: ='[6]Agregação Lvl 3-1'!E9 | L8: ='[12]Agregação Lvl 3-1'!B9 | M8: ='[12]Agregação Lvl 3-1'!C9 | N8: ='[12]Agregação Lvl 3-1'!E9
A9: Custo das passagens (R$) | B9: ED3.1 | C9: ='[5]Agregação Lvl 3-1'!B10 | D9: ='[5]Agregação Lvl 3-1'!C10 | E9: ='[5]Agregação Lvl 3-1'!E10 | F9: ='[11]Agregação Lvl 3-1'!B10 | G9: ='[11]Agregação Lvl 3-1'!C10 | H9: ='[11]Agregação Lvl 3-1'!E10 | I9: ='[6]Agregação Lvl 3-1'!B10 | J9: ='[6]Agregação Lvl 3-1'!C10 | K9: ='[6]Agregação Lvl 3-1'!E10 | L9: ='[12]Agregação Lvl 3-1'!B10 | M9: ='[12]Agregação Lvl 3-1'!C10 | N9: ='[12]Agregação Lvl 3-1'!E10
A10: Custo de outros serviços (R$) | B10: ED3.2 | C10: ='[5]Agregação Lvl 3-1'!B11 | D10: ='[5]Agregação Lvl 3-1'!C11 | E10: ='[5]Agregação Lvl 3-1'!E11 | F10: ='[11]Agregação Lvl 3-1'!B11 | G10: ='[11]Agregação Lvl 3-1'!C11 | H10: ='[11]Agregação Lvl 3-1'!E11 | I10: ='[6]Agregação Lvl 3-1'!B11 | J10: ='[6]Agregação Lvl 3-1'!C11 | K10: ='[6]Agregação Lvl 3-1'!E11 | L10: ='[12]Agregação Lvl 3-1'!B11 | M10: ='[12]Agregação Lvl 3-1'!C11 | N10: ='[12]Agregação Lvl 3-1'!E11
A11: Custo médio por viagem (R$/trip) | B11: ED3.3 | C11: ='[5]Agregação Lvl 3-1'!B12 | D11: ='[5]Agregação Lvl 3-1'!C12 | E11: ='[5]Agregação Lvl 3-1'!E12 | F11: ='[11]Agregação Lvl 3-1'!B12 | G11: ='[11]Agregação Lvl 3-1'!C12 | H11: ='[11]Agregação Lvl 3-1'!E12 | I11: ='[6]Agregação Lvl 3-1'!B12 | J11: ='[6]Agregação Lvl 3-1'!C12 | K11: ='[6]Agregação Lvl 3-1'!E12 | L11: ='[12]Agregação Lvl 3-1'!B12 | M11: ='[12]Agregação Lvl 3-1'!C12 | N11: ='[12]Agregação Lvl 3-1'!E12
A12: Contabilização do voo como parte do trabalho | B12: DF1.1 | E12: ='[5]Agregação Lvl 3-1'!E17 | H12: ='[11]Agregação Lvl 3-1'!E17 | K12: ='[6]Agregação Lvl 3-1'!E17 | N12: 1
A13: Intercâmbio sem deslocamento aéreo | B13: DF1.2 | E13: ='[5]Agregação Lvl 3-1'!E18 | H13: ='[11]Agregação Lvl 3-1'!E18 | K13: ='[6]Agregação Lvl 3-1'!E18 | N13: 0
A14: Descrição do motivo do voo | B14: DF1.3 | E14: ='[5]Agregação Lvl 3-1'!E19 | H14: ='[11]Agregação Lvl 3-1'!E19 | K14: ='[6]Agregação Lvl 3-1'!E19 | N14: 1
A15: Taxa de viagens evitáveis | B15: DF1.4 | C15: ='[5]Agregação Lvl 3-1'!B13 | D15: ='[5]Agregação Lvl 3-1'!C13 | E15: ='[5]Agregação Lvl 3-1'!E13 | F15: ='[11]Agregação Lvl 3-1'!B13 | G15: ='[11]Agregação Lvl 3-1'!C13 | H15: ='[11]Agregação Lvl 3-1'!E13 | I15: ='[6]Agregação Lvl 3-1'!B13 | J15: ='[6]Agregação Lvl 3-1'!C13 | K15: ='[6]Agregação Lvl 3-1'!E13 | L15: ='[12]Agregação Lvl 3-1'!B13 | M15: ='[12]Agregação Lvl 3-1'!C13 | N15: ='[12]Agregação Lvl 3-1'!E13
A16: Taxa de viagens urgentes não justificadas | B16: DF1.5 | C16: ='[5]Agregação Lvl 3-1'!B14 | D16: ='[5]Agregação Lvl 3-1'!C14 | E16: ='[5]Agregação Lvl 3-1'!E14 | F16: ='[11]Agregação Lvl 3-1'!B14 | G16: ='[11]Agregação Lvl 3-1'!C14 | H16: ='[11]Agregação Lvl 3-1'!E14 | I16: ='[6]Agregação Lvl 3-1'!B14 | J16: ='[6]Agregação Lvl 3-1'!C14 | K16: ='[6]Agregação Lvl 3-1'!E14 | L16: ='[12]Agregação Lvl 3-1'!B14 | M16: ='[12]Agregação Lvl 3-1'!C14 | N16: ='[12]Agregação Lvl 3-1'!E14
A17: Categoria de viagens por segmento | B17: DF2.1 | E17: ='[5]Agregação Lvl 3-1'!E20 | H17: ='[11]Agregação Lvl 3-1'!E20 | K17: ='[6]Agregação Lvl 3-1'!E20 | N17: ='[12]Agregação Lvl 3-1'!E20
A18: Uso de classe econômica | B18: IB1.1 | E18: ='[5]Agregação Lvl 3-1'!E21 | H18: ='[11]Agregação Lvl 3-1'!E21 | K18: ='[6]Agregação Lvl 3-1'!E21 | N18: 1
A19: Gerenciamento, priorização e monitoramento de voos | B19: IB1.2 | E19: ='[5]Agregação Lvl 3-1'!E22 | H19: ='[11]Agregação Lvl 3-1'!E22 | K19: ='[6]Agregação Lvl 3-1'!E22 | N19: 1
A20: Programas de mitigação de emissões aéreas | B20: IB1.3 | E20: ='[5]Agregação Lvl 3-1'!E23 | H20: ='[11]Agregação Lvl 3-1'!E23 | K20: ='[6]Agregação Lvl 3-1'!E23 | N20: 0
A21: Hibridização de Eventos e Conferências | B21: IB2.1 | E21: ='[5]Agregação Lvl 3-1'!E24 | H21: ='[11]Agregação Lvl 3-1'!E24 | K21: ='[6]Agregação Lvl 3-1'!E24 | N21: 0
A22: Acesso a alternativas ao voo | B22: IB2.2 | E22: ='[5]Agregação Lvl 3-1'!E25 | H22: ='[11]Agregação Lvl 3-1'!E25 | K22: ='[6]Agregação Lvl 3-1'!E25 | N22: 0
A23: Incentivo a participações remotas | B23: IB2.3 | E23: ='[5]Agregação Lvl 3-1'!E26 | H23: ='[11]Agregação Lvl 3-1'!E26 | K23: ='[6]Agregação Lvl 3-1'!E26 | N23: 0
A24: Inventário de viagens aéreas | B24: IB3.1 | E24: ='[5]Agregação Lvl 3-1'!E27 | H24: ='[11]Agregação Lvl 3-1'!E27 | K24: ='[6]Agregação Lvl 3-1'!E27 | N24: 1
A25: Campanhas de conscientização | B25: IB3.2 | E25: ='[5]Agregação Lvl 3-1'!E28 | H25: ='[11]Agregação Lvl 3-1'!E28 | K25: ='[6]Agregação Lvl 3-1'!E28 | N25: 0
A26: Viagens aéreas como critério de seleção | B26: IB3.3 | E26: ='[5]Agregação Lvl 3-1'!E29 | H26: ='[11]Agregação Lvl 3-1'!E29 | K26: ='[6]Agregação Lvl 3-1'!E29 | N26: 0
A27: Relatório público de emissões | B27: IB3.4 | E27: ='[5]Agregação Lvl 3-1'!E30 | H27: ='[11]Agregação Lvl 3-1'!E30 | K27: ='[6]Agregação Lvl 3-1'!E30 | N27: 0
B29: ED1 | C29: ED2 | D29: ED3 | E29: DF1 | F29: DF2 | G29: IB1 | H29: IB2 | I29: IB3 | J29: I
A30: Score 22.1 | B30: ='[5]Agregação Lvl 3-1'!K3 | C30: ='[5]Agregação Lvl 3-1'!L3 | D30: ='[5]Agregação Lvl 3-1'!M3 | E30: ='[5]Agregação Lvl 3-1'!N3 | F30: ='[5]Agregação Lvl 3-1'!O3 | G30: ='[5]Agregação Lvl 3-1'!P3 | H30: ='[5]Agregação Lvl 3-1'!Q3 | I30: ='[5]Agregação Lvl 3-1'!R3 | J30: ='[5]Agregação Lvl 3-1'!V3
A31: Score 22.2 | B31: ='[11]Agregação Lvl 3-1'!K3 | C31: ='[11]Agregação Lvl 3-1'!L3 | D31: ='[11]Agregação Lvl 3-1'!M3 | E31: ='[11]Agregação Lvl 3-1'!N3 | F31: ='[11]Agregação Lvl 3-1'!O3 | G31: ='[11]Agregação Lvl 3-1'!P3 | H31: ='[11]Agregação Lvl 3-1'!Q3 | I31: ='[11]Agregação Lvl 3-1'!R3 | J31: ='[11]Agregação Lvl 3-1'!V3
A32: Score 23.1 | B32: ='[6]Agregação Lvl 3-1'!K3 | C32: ='[6]Agregação Lvl 3-1'!L3 | D32: ='[6]Agregação Lvl 3-1'!M3 | E32: ='[6]Agregação Lvl 3-1'!N3 | F32: ='[6]Agregação Lvl 3-1'!O3 | G32: ='[6]Agregação Lvl 3-1'!P3 | H32: ='[6]Agregação Lvl 3-1'!Q3 | I32: ='[6]Agregação Lvl 3-1'!R3 | J32: ='[6]Agregação Lvl 3-1'!V3
A33: Score 23.2 | B33: ='[12]Agregação Lvl 3-1'!K3 | C33: ='[12]Agregação Lvl 3-1'!L3 | D33: ='[12]Agregação Lvl 3-1'!M3 | E33: ='[12]Agregação Lvl 3-1'!N3 | F33: ='[12]Agregação Lvl 3-1'!O3 | G33: ='[12]Agregação Lvl 3-1'!P3 | H33: ='[12]Agregação Lvl 3-1'!Q3 | I33: ='[12]Agregação Lvl 3-1'!R3 | J33: ='[12]Agregação Lvl 3-1'!V3
B35: ED | C35: DF | D35: IB | E35: I
A36: Score 22.1 | B36: ='[5]Agregação Lvl 3-1'!S3 | C36: ='[5]Agregação Lvl 3-1'!T3 | D36: ='[5]Agregação Lvl 3-1'!U3 | E36: ='[5]Agregação Lvl 3-1'!V3
A37: Score 22.2 | B37: ='[11]Agregação Lvl 3-1'!S3 | C37: ='[11]Agregação Lvl 3-1'!T3 | D37: ='[11]Agregação Lvl 3-1'!U3 | E37: ='[11]Agregação Lvl 3-1'!V3
A38: Score 23.1 | B38: ='[6]Agregação Lvl 3-1'!S3 | C38: ='[6]Agregação Lvl 3-1'!T3 | D38: ='[6]Agregação Lvl 3-1'!U3 | E38: ='[6]Agregação Lvl 3-1'!V3
A39: Score 23.2 | B39: ='[12]Agregação Lvl 3-1'!S3 | C39: ='[12]Agregação Lvl 3-1'!T3 | D39: ='[12]Agregação Lvl 3-1'!U3 | E39: ='[12]Agregação Lvl 3-1'!V3
B42: =TRANSPOSE(A30:A33) | C42: Score 22.2 | D42: Score 23.1 | E42: Score 23.2
A43: =TRANSPOSE(B29:J29) | B43: =TRANSPOSE(B30:J33) | C43: 0.65 | D43: 0.4 | E43: 0.4
A44: ED2 | B44: 0.88 | C44: 0.88 | D44: 0.7 | E44: 0.68
...

Sheet Gráficos scores

Sheet resultados emissões
B1: Emissões por viagens de até 1 dia (KgCO2eq) | G1: Custos com viagens de até 1 dia | L1: Quantidade de viagens de até 1 dia | R1: Viagens facilmente evitáveis | U1: Viagens urgentes sem justificativa
A2: Período | B2: 2022.1 | C2: 2022.2 | D2: 2023.1 | E2: 2023.2 | G2: 2022.1 | H2: 2022.2 | I2: 2023.1 | J2: 2023.2 | L2: 2022.1 | M2: 2022.2 | N2: 2023.1 | O2: 2023.2 | R2: Emissions (KgCO2eq) | S2: Cost (R$) | T2: Amount | U2: Emissions (KgCO2eq) | V2: Cost (R$) | W2: Amount
A3: Valor | B3: 999.28 | C3: 626.66 | D3: 3660.06 | E3: 3968.26 | G3: =5729.08+1031.86 | H3: =3826.01+625.07 | I3: =21773+2879.96 | J3: =16509.04+3820.07 | L3: 2 | M3: 1 | N3: 6 | O3: 7 | Q3: 2022.1 | R3: =B13 | S3: =G13 | T3: =L13 | U3: =B21 | V3: =G21 | W3: =L21
A4: Porcentagem do total | B4: =B3/'Resultados Aplicação do Modelo'!$D$2 | C4: =C3/'Resultados Aplicação do Modelo'!$G$2 | D4: =D3/'Resultados Aplicação do Modelo'!$J$2 | E4: =E3/'Resultados Aplicação do Modelo'!$M$2 | G4: =G3/(SUM('Resultados Aplicação do Modelo'!$D$9:$D$10)) | H4: =H3/(SUM('Resultados Aplicação do Modelo'!$F$9:$F$10)) | I4: =I3/(SUM('Resultados Aplicação do Modelo'!$J$9:$J$10)) | J4: =J3/(SUM('Resultados Aplicação do Modelo'!$M$9:$M$10)) | L4: =L3/'Resultados Aplicação do Modelo'!$D$6 | M4: =M3/'Resultados Aplicação do Modelo'!$G$6 | N4: =N3/(SUM('Resultados Aplicação do Modelo'!$J$6)) | O4: =O3/(SUM('Resultados Aplicação do Modelo'!$M$6)) | Q4: Avoidable flights (22.1) | R4: =B14 | S4: =G14 | T4: =L14 | U4: =B22 | V4: =G22 | W4: =L22
Q5: 2022.2 | R5: =C13 | S5: =H13 | T5: =M13 | U5: =C21 | V5: =H21 | W5: =M21
B6: Emissões por viagens muito curtas, de até 600 km (KgCO2eq) | G6: Custos com viagens muito curtas (até 600 km) | L6: Quantidade de viagens muito curtas (até 600 km) | Q6: Avoidable flights (22.2) | R6: =C14 | S6: =H14 | T6: =M14 | U6: =C22 | V6: =H22 | W6: =M22
B7: 2022.1 | C7: 2022.2 | D7: 2023.1 | E7: 2023.2 | G7: 2022.1 | H7: 2022.2 | I7: 2023.1 | J7: 2023.2 | L7: 2022.1 | M7: 2022.2 | N7: 2023.1 | O7: 2023.2 | Q7: 2023.1 | R7: =D13 | S7: =I13 | T7: =N13 | U7: =D21 | V7: =I21 | W7: =N21
B8: 274.46 | C8: 98.66 | D8: 0 | E8: 805.87 | G8: =6433.38+1294.8 | H8: =1173.24+1205.29 | I8: 0 | J8: =11130.48+12258.94 | L8: 2 | M8: 1 | N8: 0 | O8: 6 | Q8: Avoidable flights (23.1) | R8: =D14 | S8: =I14 | T8: =N14 | U8: =D22 | V8: =I22 | W8: =N22
B9: =B8/'Resultados Aplicação do Modelo'!$D$2 | C9: =C8/'Resultados Aplicação do Modelo'!$G$2 | D9: =D8/'Resultados Aplicação do Modelo'!$J$2 | E9: =E8/'Resultados Aplicação do Modelo'!$M$2 | G9: =G3/(SUM('Resultados Aplicação do Modelo'!$D$9:$D$10)) | H9: =H8/(SUM('Resultados Aplicação do Modelo'!$F$9:$F$10)) | I9: =I8/(SUM('Resultados Aplicação do Modelo'!$J$9:$J$10)) | J9: =J8/(SUM('Resultados Aplicação do Modelo'!$M$9:$M$10)) | L9: =L8/'Resultados Aplicação do Modelo'!$D$6 | M9: =M8/'Resultados Aplicação do Modelo'!$G$6 | N9: =N8/(SUM('Resultados Aplicação do Modelo'!$J$6)) | O9: =O8/(SUM('Resultados Aplicação do Modelo'!$M$6)) | Q9: 2023.2 | R9: =E13 | S9: =J13 | T9: =O13 | U9: =E21 | V9: =J21 | W9: =O21
Q10: Avoidable flights (23.2) | R10: =E14 | S10: =J14 | T10: =O14 | U10: =E22 | V10: =J22 | W10: =O22
B11: Emissões por viagens facilmente evitáveis (KgCO2eq) | G11: Custos com viagens facilmente evitáveis | L11: Quantidade de viagens facilmente evitáveis
A12: Período | B12: 2022.1 | C12: 2022.2 | D12: 2023.1 | E12: 2023.2 | G12: 2022.1 | H12: 2022.2 | I12: 2023.1 | J12: 2023.2 | L12: 2022.1 | M12: 2022.2 | N12: 2023.1 | O12: 2023.2
A13: Valor | B13: =SUM(B3,B8) | C13: =SUM(C3,C8) | D13: =SUM(D3,D8) | E13: =SUM(E3,E8) | G13: =SUM(G3,G8) | H13: =SUM(H3,H8) | I13: =SUM(I3,I8) | J13: =SUM(J3,J8) | L13: =SUM(L3,L8) | M13: =SUM(M3,M8) | N13: =SUM(N3,N8) | O13: =SUM(O3,O8)
A14: Porcentagem do total | B14: =SUM(B4,B9) | C14: =SUM(C4,C9) | D14: =SUM(D4,D9) | E14: =SUM(E4,E9) | G14: =SUM(G4,G9) | H14: =SUM(H4,H9) | I14: =SUM(I4,I9) | J14: =SUM(J4,J9) | L14: =SUM(L4,L9) | M14: =SUM(M4,M9) | N14: =SUM(N4,N9) | O14: =SUM(O4,O9)
B19: Emissões por viagens urgentes sem justificativa (KgCO2eq) | G19: Custos com viagens urgentes sem justificativa | L19: Quantidade de viagens urgentes sem justificativa
A20: Período | B20: 2022.1 | C20: 2022.2 | D20: 2023.1 | E20: 2023.2 | G20: 2022.1 | H20: 2022.2 | I20: 2023.1 | J20: 2023.2 | L20: 2022.1 | M20: 2022.2 | N20: 2023.1 | O20: 2023.2
A21: Valor | B21: 0 | C21: 0 | D21: 1066.88 | E21: 0 | G21: 0 | H21: 0 | I21: =5049.16+1645.85 | J21: 0 | L21: 0 | M21: 0 | N21: 1 | O21: 0
A22: Porcentagem do total | B22: =B21/'Resultados Aplicação do Modelo'!$D$2 | C22: =C21/'Resultados Aplicação do Modelo'!$G$2 | D22: =D21/'Resultados Aplicação do Modelo'!$J$2 | E22: =E21/'Resultados Aplicação do Modelo'!$M$2 | G22: =G16/(SUM('Resultados Aplicação do Modelo'!$D$9:$D$10)) | H22: =H21/(SUM('Resultados Aplicação do Modelo'!$F$9:$F$10)) | I22: =I21/(SUM('Resultados Aplicação do Modelo'!$J$9:$J$10)) | J22: =J21/(SUM('Resultados Aplicação do Modelo'!$M$9:$M$10)) | L22: =L21/'Resultados Aplicação do Modelo'!$D$6 | M22: =M21/'Resultados Aplicação do Modelo'!$G$6 | N22: =N21/(SUM('Resultados Aplicação do Modelo'!$J$6)) | O22: =O21/(SUM('Resultados Aplicação do Modelo'!$M$6))

Sheet Planilha1
A1: Soma de Qtd | B1: Rótulos de Coluna
A2: Rótulos de Linha | B2: Participação em Evento Acadêmico | C2: Representação em Evento Institucional | D2: Participação em Banca Avaliadora | E2: Representação em Reunião Institucional | F2: Capacitação, Treinamento ou Auditorias | G2: Outros | H2: Trabalho de Campo | I2: Intercâmbio | J2: Total Geral
A3: 2022.1 | B3: 16 | C3: 17 | D3: 24 | E3: 16 | F3: 6 | G3: 0 | H3: 0 | I3: 0 | J3: 79
A4: 2022.2 | B4: 147 | C4: 37 | D4: 6 | E4: 17 | F4: 15 | G4: 5 | H4: 2 | I4: 0 | J4: 229
A5: 2023.1 | B5: 21 | C5: 22 | D5: 25 | E5: 18 | F5: 7 | G5: 0 | H5: 0 | I5: 0 | J5: 93
A6: 2023.2 | B6: 216 | C6: 85 | D6: 29 | E6: 31 | F6: 23 | G6: 20 | H6: 5 | I6: 5 | J6: 414
A7: Total Geral | B7: 400 | C7: 161 | D7: 84 | E7: 82 | F7: 51 | G7: 25 | H7: 7 | I7: 5 | J7: 815

Sheet Resultados DF
A1: 2022.1 | C1: 2022.2 | E1: 2023.1 | G1: 2023.2 | J1: 2022.1 | L1: 2022.2 | N1: 2023.1 | P1: 2023.2 | S1: Motivo | T1: Qtd | U1: Semestre
A2: Servidor | B2: 35 | C2: Acadêmico | D2: 111 | E2: Servidor | F2: 43 | G2: Acadêmico | H2: 178 | J2: Participação em Banca Avaliadora | K2: 24 | L2: Participação em Evento Acadêmico | M2: 147 | N2: Participação em Banca Avaliadora | O2: 25 | P2: Participação em Evento Acadêmico | Q2: 216 | S2: Participação em Banca Avaliadora | T2: 24 | U2: 2022.1
A3: Representação em Reunião Institucional | B3: 16 | C3: Participação em Evento Acadêmico | D3: 99 | E3: Representação em Evento Institucional | F3: 21 | G3: Participação em Evento Acadêmico | H3: 128 | J3: Externo | K3: 12 | L3: Acadêmico | M3: 99 | N3: Acadêmico | O3: 12 | P3: Acadêmico | Q3: 128 | S3: Representação em Evento Institucional | T3: 17 | U3: 2022.1
A4: Representação em Evento Institucional | B4: 16 | C4: Representação em Evento Institucional | D4: 5 | E4: Representação em Reunião Institucional | F4: 18 | G4: Participação em Banca Avaliadora | H4: 21 | J4: Acadêmico | K4: 11 | L4: Discente | M4: 30 | N4: Externo | O4: 12 | P4: Discente | Q4: 53 | S4: Representação em Reunião Institucional | T4: 16 | U4: 2022.1
A5: Capacitação, Treinamento ou Auditorias | B5: 2 | C5: Capacitação, Treinamento ou Auditorias | D5: 3 | E5: Capacitação, Treinamento ou Auditorias | F5: 3 | G5: Representação em Evento Institucional | H5: 14 | J5: Servidor | K5: 1 | L5: Externo | M5: 17 | N5: Servidor | O5: 1 | P5: Servidor | Q5: 19 | S5: Participação em Evento Acadêmico | T5: 16 | U5: 2022.1
A6: Participação em Banca Avaliadora | B6: 1 | C6: Participação em Banca Avaliadora | D6: 2 | E6: Participação em Banca Avaliadora | F6: 1 | G6: Representação em Reunião Institucional | H6: 6 | J6: Representação em Evento Institucional | K6: 17 | L6: Servidor | M6: 1 | N6: Representação em Evento Institucional | O6: 22 | P6: Externo | Q6: 16 | S6: Capacitação, Treinamento ou Auditorias | T6: 6 | U6: 2022.1
A7: Acadêmico | B7: 24 | C7: Trabalho de Campo | D7: 1 | E7: Acadêmico | F7: 29 | G7: Capacitação, Treinamento ou Auditorias | H7: 5 | J7: Servidor | K7: 16 | L7: Representação em Evento Institucional | M7: 37 | N7: Servidor | O7: 21 | P7: Representação em Evento Institucional | Q7: 85 | S7: Participação em Evento Acadêmico | T7: 147 | U7: 2022.2
A8: Participação em Banca Avaliadora | B8: 11 | C8: Representação em Reunião Institucional | D8: 1 | E8: Participação em Evento Acadêmico | F8: 14 | G8: Trabalho de Campo | H8: 3 | J8: Externo | K8: 1 | L8: Servidor | M8: 17 | N8: Externo | O8: 1 | P8: Servidor | Q8: 69 | S8: Representação em Evento Institucional | T8: 37 | U8: 2022.2
A9: Participação em Evento Acadêmico | B9: 10 | C9: Servidor | D9: 43 | E9: Participação em Banca Avaliadora | F9: 12 | G9: Intercâmbio | H9: 1 | J9: Representação em Reunião Institucional | K9: 16 | L9: Externo | M9: 15 | N9: Participação em Evento Acadêmico | O9: 21 | P9: Acadêmico | Q9: 14 | S9: Representação em Reunião Institucional | T9: 17 | U9: 2022.2
A10: Capacitação, Treinamento ou Auditorias | B10: 3 | C10: Representação em Evento Institucional | D10: 17 | E10: Capacitação, Treinamento ou Auditorias | F10: 3 | G10: Servidor | H10: 132 | J10: Servidor | K10: 16 | L10: Acadêmico | M10: 5 | N10: Acadêmico | O10: 14 | P10: Externo | Q10: 2 | S10: Capacitação, Treinamento ou Auditorias | T10: 15 | U10: 2022.2
A11: Externo | B11: 17 | C11: Representação em Reunião Institucional | D11: 16 | E11: Externo | F11: 18 | G11: Representação em Evento Institucional | H11: 69 | J11: Participação em Evento Acadêmico | K11: 16 | L11: Representação em Reunião Institucional | M11: 17 | N11: Externo | O11: 4 | P11: Representação em Reunião Institucional | Q11: 31 | S11: Participação em Banca Avaliadora | T11: 6 | U11: 2022.2
A12: Participação em Banca Avaliadora | B12: 12 | C12: Capacitação, Treinamento ou Auditorias | D12: 7 | E12: Participação em Banca Avaliadora | F12: 12 | G12: Representação em Reunião Institucional | H12: 23 | J12: Acadêmico | K12: 10 | L12: Servidor | M12: 16 | N12: Discente | O12: 3 | P12: Servidor | Q12: 23 | S12: Outros | T12: 5 | U12: 2022.2
A13: Participação em Evento Acadêmico | B13: 3 | C13: Outros | D13: 2 | E13: Participação em Evento Acadêmico | F13: 4 | G13: Participação em Evento Acadêmico | H13: 19 | J13: Discente | K13: 3 | L13: Acadêmico | M13: 1 | N13: Representação em Reunião Institucional | O13: 18 | P13: Acadêmico | Q13: 6 | S13: Trabalho de Campo | T13: 2 | U13: 2022.2
... A18: Total (2022.1) | B18: 79 | C18: Capacitação, Treinamento ou Auditorias | D18: 4 | E18: Total Geral | F18: 93 | G18: Intercâmbio | H18: 4 | J18: Externo | K18: 1 | L18: Discente | M18: 1 | N18: Externo | O18: 1 | P18: Capacitação, Treinamento ou Auditorias | Q18: 23 | S18: Capacitação, Treinamento ou Auditorias | T18: 7 | U18: 2023.1
C19: Participação em Banca Avaliadora | D19: 4 | G19: Representação em Reunião Institucional | H19: 2 | J19: Total (2022.1) | K19: 79 | L19: Participação em Banca Avaliadora | M19: 6 | N19: Total Geral | O19: 93 | P19: Servidor | Q19: 15 | S19: Participação em Evento Acadêmico | T19: 216 | U19: 2023.2
C20: Outros | D20: 1 | G20: Trabalho de Campo | H20: 2 | L20: Externo | M20: 4 | P20: Acadêmico | Q20: 5 | S20: Representação em Evento Institucional | T20: 85 | U20: 2023.2
C21: Discente | D21: 34 | G21: Capacitação, Treinamento ou Auditorias | H21: 2 | L21: Acadêmico | M21: 2 | P21: Discente | Q21: 2 | S21: Representação em Reunião Institucional | T21: 31 | U21: 2023.2
C22: Participação em Evento Acadêmico | D22: 30 | G22: Externo | H22: 41 | L22: Outros | M22: 5 | P22: Externo | Q22: 1 | S22: Participação em Banca Avaliadora | T22: 29 | U22: 2023.2
C23: Outros | D23: 2 | G23: Participação em Evento Acadêmico | H23: 16 | L23: Servidor | M23: 2 | P23: Outros | Q23: 20 | S23: Capacitação, Treinamento ou Auditorias | T23: 23 | U23: 2023.2
C24: Capacitação, Treinamento ou Auditorias | D24: 1 | G24: Outros | H24: 14 | L24: Discente | M24: 2 | P24: Externo | Q24: 14 | S24: Outros | T24: 20 | U24: 2023.2
C25: Trabalho de Campo | D25: 1 | G25: Participação em Banca Avaliadora | H25: 8 | L25: Externo | M25: 1 | P25: Servidor | Q25: 6 | S25: Trabalho de Campo | T25: 5 | U25: 2023.2
C26: Total (2022.2) | D26: 229 | G26: Representação em Evento Institucional | H26: 2 | L26: Trabalho de Campo | M26: 2 | P26: Trabalho de Campo | Q26: 5 | S26: Intercâmbio | T26: 5 | U26: 2023.2
G27: Capacitação, Treinamento ou Auditorias | H27: 1 | L27: Discente | M27: 1 | P27: Acadêmico | Q27: 3
G28: Total Geral | H28: 414 | L28: Acadêmico | M28: 1 | P28: Discente | Q28: 2
L29: Total (2022.2) | M29: 229 | P29: Intercâmbio | Q29: 5
P30: Discente | Q30: 4
P31: Acadêmico | Q31: 1
P32: Total Geral | Q32: 414

Sheet Resultados IB
